issue,id,reporter,closed_by,created_at,updated_at,closed_at,state,assignee,milestone,comments,label_name,url,title,body
xonsh/xonsh#726,139157731,asmeurer,,2016-03-08 02:27:30,2016-07-12 13:24:30,None,open,,v0.4.0,35,bug,https://api.github.com/repos/xonsh/xonsh/issues/726,b'Prompt colors are different between readline and prompt_toolkit ',"b'The readline shell looks like \r\n\r\n<img width=""143"" alt=""screen shot 2016-03-07 at 9 25 48 pm"" src=""https://cloud.githubusercontent.com/assets/71486/13590097/2e3ad716-e4ab-11e5-9ff8-4f62888ba4e4.png"">\r\n\r\nThe prompt_toolkit shell looks like\r\n\r\n<img width=""157"" alt=""screen shot 2016-03-07 at 9 26 15 pm"" src=""https://cloud.githubusercontent.com/assets/71486/13590100/38003520-e4ab-11e5-9da3-c07c55d8425b.png"">\r\n\r\nI am using BOLD_CYAN (see https://github.com/asmeurer/dotfiles/blob/a55ec501eed8e99de0e2f33d0a9031fa78569539/.xonshrc#L156).  My bash prompt looks like the readline one here, and is what I want. '"
,,,,,,,,,,,,,,
ludwigschwardt/python-gnureadline#43,72450393,bobwaycott,ludwigschwardt,2015-05-01 15:08:29,2015-11-24 09:43:54,2015-05-07 07:18:36,closed,,,11,,https://api.github.com/repos/ludwigschwardt/python-gnureadline/issues/43,b'OS X + PyPy support?',"b""Hey, I was just wondering if you've ever tried installing `python-gnureadline` with pypy?\r\n\r\nI use `pyenv` on my OS X Yosemite machine, and have a virtualenv setup for pypy. Seems I can't get the pkg to successfully install under pypy, while I have no issues under non-pypy Python 2.7.x versions installed & managed through `pyenv virtualenv`.\r\n\r\nI thought I'd check generally on your support for PyPy before filing an issue with pip failure output. No sense in doing all that if it's something you know you don't want to support, right? :)"""
pickleshare/pickleshare#8,103504203,chrisidefix,minrk,2015-08-27 13:07:03,2016-01-19 20:51:37,2016-01-19 20:51:37,closed,,,11,,https://api.github.com/repos/pickleshare/pickleshare/issues/8,b'Path was updated to 8.0 and causes incompatibility.',"b'Currently, if you update `path.py` to the latest release it no longer works with `pickleshare`. In particular, when running `ipython` you may receive this error:\r\n```\r\nTraceback (most recent call last):\r\n  File ""/usr/local/bin/ipython"", line 7, in <module>\r\n    from IPython import start_ipython\r\n  File ""/usr/local/lib/python2.7/site-packages/IPython/__init__.py"", line 48, in <module>\r\n    from .terminal.embed import embed\r\n  File ""/usr/local/lib/python2.7/site-packages/IPython/terminal/embed.py"", line 16, in <module>\r\n    from IPython.core.interactiveshell import DummyMod\r\n  File ""/usr/local/lib/python2.7/site-packages/IPython/core/interactiveshell.py"", line 31, in <module>\r\n    from pickleshare import PickleShareDB\r\n  File ""/usr/local/lib/python2.7/site-packages/pickleshare.py"", line 41, in <module>\r\n    from path import path as Path\r\nImportError: cannot import name path\r\n```\r\n\r\nSee this commit: https://github.com/jaraco/path.py/commit/62ccb7623d4d048af663f205e21c2ec3f24fa17d\r\n\r\nFor now, I just downgraded to [path.py 7.7.1](https://github.com/jaraco/path.py/releases/tag/7.7.1), but any chance you will release a fix for this?'"
jupyter/notebook#973,127459636,minrk,,2015-03-17 16:14:15,2016-06-16 08:16:12,None,open,,5.0,4,bug,https://api.github.com/repos/jupyter/notebook/issues/973,b'kernel_ready.Kernel triggered twice when creating a new notebook',"b'@neilzimmerman opened ipython/ipython#8069\n\nAny time you a pushed directly into a new notebook, the \'kernel_ready.Kernel\' is triggered twice from kernel.js. This usually happens when creating a new notebook or ""making a copy"" from within a running notebook.\r\n'"
dela3499/assay-explorer#12,85264734,dela3499,dela3499,2015-06-04 20:33:12,2015-06-05 00:20:41,2015-06-05 00:20:41,closed,,,1,bug,https://api.github.com/repos/dela3499/assay-explorer/issues/12,"b""Can't multiple-select via control-click on any of the widgets. """,
chjj/term.js#60,57677259,fperez,,2015-02-14 02:16:53,2015-02-14 03:07:23,None,open,,,2,,https://api.github.com/repos/chjj/term.js/issues/60,b'Rendering of certain whole-screen applications (like mc) is broken.',"b""# Context\r\n\r\nThis originated as ipython/ipython#7782 on IPython, but it seems that it's better reported directly here. IPython uses term.js purely as a component, wrapped in terminado, a Tornado-based async server. It then exposes the terminals in the IPython Notebook application.\r\n\r\n# The issue\r\n\r\nOn Chrome on Linux, if I set the Consolas font to being my monospaced font, when running mc (Midnight Commander) in the terminal, the computation of the column width must be wrong, b/c the page misrenders:\r\n\r\n![image](https://cloud.githubusercontent.com/assets/57394/6197637/d26ca638-b39d-11e4-8445-12a68b919157.png)\r\n\r\nThis is even more evident when an error box is drawn:\r\n\r\n![image](https://cloud.githubusercontent.com/assets/57394/6197640/db82257c-b39d-11e4-85df-2279bee71cf8.png)\r\n\r\nChecking the value of `Terminal.brokenBold` in the JS Console returns `true` with Consolas. Yet, the fix in ipython/ipython#7242 isn't helping here.\r\n\r\nFor reference, switching to another monospaced font, such as DejaVu Sans Mono, fixes the problem. So at least there's a workaround.\r\n\r\nBut even if the bug is in Consolas, it would be nice if we could make it work correctly (if viable).  Regular terminal emulators don't exhibit this behavior.  As noted by @takluyver in ipython/ipython#7242, this may not be easily fixable without way too much work. If that's the case, so be it, at least this will document the problem for future users.\r\n\r\nps - for extra details on this issue from the IPython side, see ipython/ipython#7242."""
winpython/winpython#34,52626297,stonebig,stonebig,2014-12-22 07:33:15,2015-08-02 06:57:10,2015-08-02 06:56:23,closed,,,28,help wanted,https://api.github.com/repos/winpython/winpython/issues/34,b'PyQt5 transition',"b""The Qt5 transition will occure during 2015, as Official PyQt4 support dies end 2015.\r\n==> That simplifies decisions a bit.\r\n\r\nQt5.5 , released arounf june 2015, deprecates Qt Webkit, in favor of QtWebEngine (Chromium 40).\r\n==> That looks the version to target \r\n\r\nfrom a MinRK comment:\r\n````\r\nYou need to use Qt5 for websocket support\r\nQt4 only supports the pre-release drafts of websockets, which IPython (tornado, really) doesn't support\r\n````\r\n\r\nSo having Spyder embedding a IPython Notebook means having Qt5.\r\nHaving Qt5 for Python2.7 won't happen unless Christoph Gohlke provides a binary for Python2.7\r\nhttp://python.6.x6.nabble.com/Windows-installers-for-PyQt5-and-Python2-td5036304.html\r\n\r\nThis tries to summary what needs to be done:\r\n- [x] WPPM is Qt5/Qt4 compatible on  (as Python2.7/3.3 may not make it to Qt5)\r\n- [x] do an internal alpha to see what happens\r\n- [x] IPython3 qtconsole supports roughly Qt5 (https://github.com/ipython/ipython/issues/7707)\r\n- [x] formlayout is maintained in spyder (`from spyderlib.widgets.formlayout import fedit`), but this part seems tricky to use from outside)\r\n- [x] pyqtgraph as the suggested alternative to guiqwt + PyQwt \r\n- [x] find a PyQt5 wheel (or just figure out how Pierre Raybaut was doing before)\r\n- [x] fix QtDemo icon for PyQt5\r\n- [x] workaround for `set QT_API=pyqt5' (for wppm)\r\n- [x] make.py strategy to detect install need of PyQt5\r\n- [x] Spyder master of july 16th + Qt5 patch works !\r\n- [x] Qt 5.5 + patch Winpython, for current Spyder to work\r\n- [x] Spyder 2.4 or 3.0 to support Qt5 (not 2.3)\r\n- [ ] guidata, PyQtdesignerplugins  replacement for PyQt5  (or none)\r\n- [ ] https://github.com/rwarren/qt_backport may be also a lower level solution\r\n- [ ] there seems to be  a `Six`-for-qt like solution https://github.com/avalentino/qtsix\r\n"""
spyder-ide/spyder#2108,57993137,spyder-issues-migrator,spyder-issues-migrator,2015-02-17 22:33:05,2015-02-17 22:33:07,2015-02-17 22:33:07,closed,,v2.3.3,2,2¨C5 stars;Comp-Console-IPython;Type-Bug,https://api.github.com/repos/spyder-ide/spyder/issues/2108,b'UnicodeDecodeError in the Internal console when trying to run a file with non-ascii chars and synatx errors in it',b'_From [ccordoba12](https://code.google.com/u/ccordoba12/) on 2015-01-09T09:44:45Z_\n\nThis issue is motivated by this StackOverflow question: http://stackoverflow.com/questions/27834477/unicode-decode-error-report-in-spyder?noredirect=1#comment44107369_27834477\n\n_Original issue: http://code.google.com/p/spyderlib/issues/detail?id=2108_'
codemirror/CodeMirror#3009,53013799,rheber,marijnh,2014-12-29 00:32:38,2014-12-29 12:13:47,2014-12-29 12:13:47,closed,,,1,,https://api.github.com/repos/codemirror/CodeMirror/issues/3009,b'Test fails on Firefox',b'In Firefox 33.0 on Windows 7 the test scroll_movedown_hscroll_fixed currently fails.'
codemirror/CodeMirror#3022,53778809,Carreau,marijnh,2015-01-08 17:44:27,2015-01-09 17:22:49,2015-01-09 17:15:39,closed,,,2,,https://api.github.com/repos/codemirror/CodeMirror/issues/3022,"b'4.10.0 badly tagged ? (still scrollbar issues, but on chrome OSX)'","b'Hey Marijnh, it seem like the scrollbar fix : https://github.com/codemirror/CodeMirror/commit/198d00f80882e80e0f5cd4f4dff1249541e36ed8 for  https://github.com/codemirror/CodeMirror/issues/3009\r\n\r\nDid not make it to the tagged version: https://github.com/codemirror/CodeMirror/blob/4.10.0/lib/codemirror.js#L778-L783 \r\n\r\n(still named plus gap instead of total)\r\n\r\nWhich make 4.10 still have the scrollbar issue in some cases eg: https://github.com/ipython/ipython/issues/7395\r\n\r\nAny chance to have a 4.10.1 ? \r\n\r\nThanks !\r\n\r\n'"
jupyter/nbconvert#145,113167154,matiasdahl,minrk,2015-10-24 15:27:45,2015-10-27 12:42:33,2015-10-27 12:42:33,closed,,4.1,1,,https://api.github.com/repos/jupyter/nbconvert/issues/145,b'markdown fields rendered as `<IPython.core.display.Markdown object>`',"b'The following creates a Markdown-formatted output cell:\r\n\r\n![example](https://cloud.githubusercontent.com/assets/10188263/10711052/d65be130-7a78-11e5-8171-1597fe797edb.png)\r\n\r\nViewing the saved .ipynb file shows the following fields in the above cell\'s `outputs` fields:\r\n\r\n```\r\n ""data"": {\r\n      ""text/markdown"": [\r\n       ""*Markdown*""\r\n      ],\r\n      ""text/plain"": [\r\n       ""<IPython.core.display.Markdown object>""\r\n      ]\r\n  }\r\n```\r\nHowever, when converting the notebook to markdown using nbconvert as\r\n```\r\n   jupyter nbconvert --execute --to markdown md_output.ipynb --stdout\r\n```\r\nthe cell\'s output is rendered as `<IPython.core.display.Markdown object>` (and not as *Markdown*).\r\nThis seems similar to  [issue 7394](https://github.com/ipython/ipython/issues/7394) for ipython.\r\n\r\n-----\r\n\r\nIn markdown.tpl, the output is rendered by the [following block](https://github.com/jupyter/nbconvert/blob/master/nbconvert/templates/markdown.tpl#L59-L61):\r\n\r\n```\r\n{% block data_text scoped %}\r\n{{ output.data[\'text/plain\'] | indent }}\r\n{% endblock data_text %}\r\n```\r\nA (quick?) workaround is to just override the block by using the following template:\r\n```\r\n{%- extends \'markdown.tpl\' -%}\r\n\r\n{% block data_text scoped %}\r\n{{ output.data[\'text/markdown\'] }}\r\n{% endblock data_text %}\r\n```\r\n\r\n(Jupyter 4.0.6)'"
matplotlib/matplotlib#3965,53323280,tacaswell,pelson,2015-01-04 03:05:33,2015-01-11 22:43:44,2015-01-11 21:42:00,closed,,v1.4.3,38,,https://api.github.com/repos/matplotlib/matplotlib/issues/3965,b'Js fixes for key events + ipython notebooks',"b""First pass at getting key events to work in ipython notebooks\r\n\r\nCloses #3963\r\n\r\nDemo, mouse over the figure to give it focus.  Clicking any mouse button or pushing any key should color-cycle the line.\r\n\r\n```python\r\nimport matplotlib\r\nimport itertools\r\nimport numpy as np\r\nmatplotlib.use('nbagg')\r\nimport matplotlib.pyplot as plt\r\nplt.close('all')\r\nfig, ax = plt.subplots()\r\nx = np.linspace(0,10,10000)\r\ny = np.sin(x)\r\nln, = ax.plot(x,y)\r\nevt = []\r\ncolors = iter(itertools.cycle(['r', 'g', 'b', 'k', 'c']))\r\ndef on_event(event):\r\n    evt.append(event)\r\n    ln.set_color(next(colors))\r\n    fig.canvas.draw()\r\n    fig.canvas.draw_idle()\r\nfig.canvas.mpl_connect('button_press_event', on_event)\r\nfig.canvas.mpl_connect('key_press_event', on_event)\r\nplt.show()\r\n```\r\n\r\nRemaining issues:\r\n - [x] mousing out of the figure area does not release focus, is this the correct behavior?\r\n - [x] not sure I injected the extra style at the right place in the DOM or than I used the right pattern to do it"""
matplotlib/matplotlib#3962,53260301,beojan,tacaswell,2015-01-02 16:07:16,2015-01-15 15:49:22,2015-01-15 15:49:22,closed,,v1.4.3,11,confirmed bug;upstream fix required,https://api.github.com/repos/matplotlib/matplotlib/issues/3962,b'No image appears with nbagg',b'See issue https://github.com/ipython/ipython/issues/7351'
matplotlib/matplotlib#4002,54395018,minrk,tacaswell,2015-01-14 23:58:16,2015-01-19 17:12:41,2015-01-15 15:38:33,closed,,v1.4.3,3,,https://api.github.com/repos/matplotlib/matplotlib/issues/4002,b'fix find_output_cell for IPython >= 3.0 [backport to 1.4.x]',"b'output mime-type keys moved from top-level to a `data` attribute.\n\nAdded an error-log for the case where output is not found, which should make similar bugs a bit easier to find in the future.\n\ncloses ipython/ipython#7351'"
jupyter/notebook#45,70268749,takluyver,rgbkrk,2015-04-23 00:27:49,2015-12-01 10:00:40,2015-05-07 14:48:37,closed,,no action,6,,https://api.github.com/repos/jupyter/notebook/issues/45,b'Use name ignored by dropbox for atomic saving temp files',"b""See discussion on ipython/ipython#8322\r\n\r\nBy using a '.~' prefix for the temporary files, Dropbox should ignore them, which makes atomic saving a bit less inconvenient.\r\n\r\nHowever, to do this, we need to switch back from using temporary directories (implemented in ipython/ipython#7469). This uses the other approach described in ipython/ipython#7317 instead."""
matplotlib/matplotlib#3932,52294171,eyurtsev,tacaswell,2014-12-17 21:28:43,2014-12-19 20:57:29,2014-12-18 02:41:25,closed,,unassigned,6,needs clarification,https://api.github.com/repos/matplotlib/matplotlib/issues/3932,b'ConnectionPatch with log scale and non-positive starting coordinates fails to produce a figure',"b'The 2nd block of code fails to produce \r\n\r\nmatplotlib v1.4.2\r\n\r\n```python\r\n%pylab inline\r\nfrom matplotlib.patches import Arrow, ConnectionPatch\r\n\r\n# This figure shows up\r\nfigure()\r\nax = gca()\r\np = Arrow(-1, -1, 2, 2)\r\nax.add_artist(p)\r\nxscale(\'log\')\r\n\r\n# This figure does not show up (even if xlimits are specified)\r\nfigure()\r\nax = gca()\r\nxy1 = (0, 0) # non-positive starting coordinate\r\nxy2 = (1, 1)\r\ncon = ConnectionPatch(xyA=xy1, xyB=xy2, coordsA=""data"", coordsB=""data"",\r\n                      axesA=ax, axesB=ax)\r\n\r\nax.add_artist(con)\r\nxscale(\'log\')\r\n```'"
Calysto/metakernel#51,48258297,dsblank,blink1073,2014-11-10 12:14:16,2014-11-10 23:02:29,2014-11-10 23:02:29,closed,,,6,,https://api.github.com/repos/Calysto/metakernel/issues/51,b'Command-line history is not saved when shutdown',"b""I can't find any method that is called to insert a save_history() function so that on restart, there is a persistent command-line history. Also, the history may not be loaded on start up."""
SciRuby/iruby#19,80869725,minad,minad,2015-05-26 09:01:29,2015-06-01 10:38:31,2015-06-01 10:38:31,closed,,,1,,https://api.github.com/repos/SciRuby/iruby/issues/19,b'Timeout at startup',b'Timeout waiting for kernel_info reply from ...\r\n\r\nSomethings wrong with 0mq at startup.'
ipython/ipywidgets#163,107577189,jdfreder,,2015-09-21 19:02:38,2015-09-21 19:02:38,None,open,,wishlist,0,discussion,https://api.github.com/repos/ipython/ipywidgets/issues/163,b'Same widget does not update all interact.',"b""Originally entered by @Carreau in https://github.com/ipython/ipython/issues/6534\r\n\r\n---\r\n\r\nCf [Stackoverflow](https://stackoverflow.com/questions/25945543/can-values-from-ipython-widgets-propagate-to-other-cells/25992790#25992790) \r\n\r\nhaving the same widget (say a Checkbox) shared by 2 interact, the value of the checkbox is updated across cell, but the interactived' function not call. Ex:\r\n\r\n\r\n![capture d ecran 2014-09-24 a 08 30 40](https://cloud.githubusercontent.com/assets/335567/4384325/e7c2de98-43b4-11e4-9264-74546270de13.png)\r\n\r\nI clicked on first checkbox, second was highligted, but value did not changed from True to False."""
,,,,,,,,,,,,,,
cython/cython#322,43312623,Carreau,scoder,2014-09-20 15:32:16,2014-09-21 16:15:12,2014-09-21 15:23:07,closed,,,2,,https://api.github.com/repos/cython/cython/issues/322,b'Fix caching issues of cython magic.',b'Should fix https://github.com/ipython/ipython/issues/6507 when using cython magic. \r\nWe will deprecate cython magic in IPython itself.'
gibiansky/IHaskell#269,39065617,cblp,gibiansky,2014-07-30 07:05:26,2015-03-06 22:49:44,2015-03-06 22:49:41,closed,,,2,,https://api.github.com/repos/gibiansky/IHaskell/issues/269,"b'Notebook: In popup completion list, down key moves edit cursor in text, not selection in comletion list'","b""Up key moves selection in completion list, it's ok.\r\n\r\nSpacebar selects next completion, but it's too unnatural to use space/up to select completion.\r\n\r\nIn IPython, everything is ok, I can select completion with up/down keys.\r\n\r\nIHaskell 0.4.1.0\r\nbrowsers: Yandex 14.5, Safari 7.0.5, Firefox 25.0.1"""
,,,,,,,,,,,,,,
mwaskom/seaborn#246,39356669,mwaskom,mwaskom,2014-08-02 20:34:36,2015-01-19 20:43:45,2015-01-19 20:43:45,closed,,v0.4,1,bug;docs;infrastructure,https://api.github.com/repos/mwaskom/seaborn/issues/246,b'IPython 2.0 breaks the tutorials',b'See [here](https://github.com/ipython/ipython/issues/6262) for a description.'
PyMVPA/PyMVPA#249,44818189,octomike,nno,2014-10-03 16:03:02,2016-01-17 18:45:35,2016-01-17 18:45:35,closed,,,5,,https://api.github.com/repos/PyMVPA/PyMVPA/issues/249,b'ZMQError: Address already in use when using nproc= in sphere_searchlight()',"b'My issue is basically: https://github.com/ipython/ipython/issues/6109\r\nI simply cannot use pprocess with sphere_searchlight() inside a notebook.\r\n\r\nI know this is not really a pymvpa problem but I was wondering how you manage to work around this, since upgrading to python 3.4 is not really an option here. Or am I doing t wrong?\r\n\r\n\r\n'"
celery/billiard#127,48501605,jamescasbon,ask,2014-11-12 11:46:31,2015-04-17 12:53:41,2015-04-17 12:53:41,closed,,,2,,https://api.github.com/repos/celery/billiard/issues/127,b'Consider porting python 3.4 forkserver into billiard',"b'There are quite a few people, including [Ipython notebook users](https://github.com/ipython/ipython/issues/6109) who could benefit from this [feature](https://docs.python.org/3/whatsnew/3.4.html#whatsnew-multiprocessing-no-fork).  Is billiard the right place for this?\r\n\r\nI note that [subprocess32](http://code.google.com/p/python-subprocess32/) already has the c extension backported that does the forking.'"
zeromq/pyzmq#613,47897502,klaussfreire,minrk,2014-11-05 22:33:28,2014-11-10 18:31:51,2014-11-10 18:31:51,closed,,,3,,https://api.github.com/repos/zeromq/pyzmq/issues/613,b'GarbageCollectorThread bad bind after fork',"b""The recent fix for the bind-after-fork in GarbageCollectorThread isn't enough. There is still a case in which the new thread can fail to bind (and thus fail to garbage collect), because the context in the GarbageCollector object is no longer valid after a fork.\r\n\r\nThe following code exhibits the issue:\r\n\r\n```python\r\nimport zmq\r\nimport os\r\n\r\nm = zmq.Message('')\r\npid = os.fork()\r\nif pid:\r\n    os.waitpid(pid, 0)\r\nelse:\r\n    m = zmq.Message('b')\r\n```\r\n\r\nApplying the patch in the following commit seems to successfully resolve the issue:\r\n\r\nhttps://github.com/klaussfreire/pyzmq/commit/3ad988dc43ef443bd206aab03d953f8c2f145a67\r\n\r\nI would make a pull request, but I'm working on other improvements on that branch and I cannot find how to cherry-pick commits for a pull request nor how to fork again (github doesn't seem to be letting me create another fork).\r\n\r\nIt would be nice to turn the above code snippet into a test, but that requires some smarts to avoid it hanging indefinitely in some cases, so the commit contains no test.\r\n"""
stan-dev/pystan#142,56630519,kforeman,ariddell,2015-02-05 05:50:52,2016-06-06 13:54:54,2016-06-06 13:54:54,closed,,3.0,24,,https://api.github.com/repos/stan-dev/pystan/issues/142,b'Parallel chains hanging in IPython Notebook',"b'With 2.5.0.2 when I run multiple chains in parallel inside of an IPython Notebook, it hangs after sampling has finished. It gets stuck on `sampling()`, but checking the terminal for stdout shows that all chains have completed. If I interrupt the kernel I get the following error:\r\n\r\n```\r\nException in thread Thread-10:\r\nTraceback (most recent call last):\r\n  File ""/Users/kforeman/anaconda/python.app/Contents/lib/python2.7/threading.py"", line 810, in __bootstrap_inner\r\n    self.run()\r\n  File ""/Users/kforeman/anaconda/lib/python2.7/site-packages/zmq/utils/garbage.py"", line 46, in run\r\n    s.bind(self.gc.url)\r\n  File ""socket.pyx"", line 444, in zmq.backend.cython.socket.Socket.bind (zmq/backend/cython/socket.c:4076)\r\n  File ""checkrc.pxd"", line 21, in zmq.backend.cython.checkrc._check_rc (zmq/backend/cython/socket.c:6032)\r\nZMQError: Address already in use\r\n```\r\n\r\nSeems like it may be related to [this issue](https://github.com/ipython/ipython/issues/6109) which implies that using Python\'s `multiprocessing` module from within IPython can cause issues. So maybe this is just an inherent issue with using multiprocessing from within IPython, but the strange thing is I had previously run multiple chains in an IPython notebook in 2.4.0.3.'"
jdfreder/notebook_cherry_picker#3,31795448,JohnGriffiths,,2014-04-18 12:05:02,2014-04-18 23:06:30,None,open,,,4,,https://api.github.com/repos/jdfreder/notebook_cherry_picker/issues/3,"b""'not' syntax for cell filtering""","b'I\'ve been trying use a \'not\' syntax for the cherry picker expression and am getting funny results for what I would have thought should be the correct code. \r\n\r\nSuppose I have succesfully set up TAGs 1-3, and used the cell toolbar to tick them as desired. \r\n\r\nWhat would be the syntax for removing cells tagged with TAG1?\r\n\r\nThis doesn\'t seem to be working for me\r\n\r\n    \' --CherryPickingPreprocessor.expression=""not TAG1""\'\r\n\r\nIs that incorrect?\r\n\r\nTa. \r\n\r\n\r\n'"
,,,,,,,,,,,,,,
jupyter/nbviewer#211,28929958,ellisonbg,rgbkrk,2014-03-07 00:59:51,2014-06-26 15:39:35,2014-03-08 04:03:57,closed,,,6,,https://api.github.com/repos/jupyter/nbviewer/issues/211,b'Add require.js to static/components and load jQuery/require.js at the top of the page',"b'This PR is to address this issue:\r\n\r\nhttps://github.com/ipython/ipython/issues/5084\r\n\r\nIt adds a bower based require.js to `static/components` and puts both jQuery and require.js at the top of the body so they are available to subsequently loaded notebook cells.\r\n\r\n@rgbkrk can we try this out on a test server first?\r\n\r\nAlso, I put these at the top of the body. Better to put them in the head?'"
,,,,,,,,,,,,,,
pydata/pandas#6225,26753618,michaelaye,y-p,2014-02-02 03:34:02,2014-02-02 06:02:28,2014-02-02 05:54:16,closed,,0.13.1,3,,https://api.github.com/repos/pydata/pandas/issues/6225,b'Weird error in master when asked for type(df)',"b""```python\r\nIn [9]: type(detectors)\r\nWARNING: Exception in text/html formatter: unbound method _repr_html_() must be called with DataFrame instance as first argument (got nothing instead)\r\nOut[9]:\r\npandas.core.frame.DataFrame\r\nIn [10]: detectors.info()\r\n<class 'pandas.core.frame.DataFrame'>\r\nDatetimeIndex: 1565757 entries, 2008-01-08 17:15:29.111000 to 2008-01-18 07:57:01.504000\r\nData columns (total 4 columns):\r\na6_11    1565757  non-null values\r\nb1_11    1565757  non-null values\r\nb2_11    1565757  non-null values\r\nb3_11    1565757  non-null values\r\ndtypes: int64(4)\r\nIn [11]: \r\npd.__version__\r\nOut[11]:\r\n'0.13.0rc1-59-g90990db'\r\n```\r\nI noticed another oddity: Why does the type-display create an output numbering (=Out[9]) but the display of detectors.info() does not? Something to do with IPython?\r\n"""
,,,,,,,,,,,,,,
,,,,,,,,,,,,,,
,,,,,,,,,,,,,,
,,,,,,,,,,,,,,
jgm/pandoc#469,3907173,cboettig,jgm,2012-03-31 00:26:40,2014-03-17 23:19:04,2012-04-06 18:42:44,closed,,,19,,https://api.github.com/repos/jgm/pandoc/issues/469,b'errors on latex tables with math markup',"b""It's rather excellent that pandoc can take markdown with latex tables.  Unfortunately, it fails when there is math in markup in the table, [as in this example](https://raw.github.com/cboettig/sandbox/master/pandoc_latex_tables.md)\r\n\r\n(This table is created by running [knitr](https://github.com/yihui/knitr) on this [markdown file](https://raw.github.com/cboettig/sandbox/master/pandoc_latex_tables_knit_.md), where xtable is creating the latex table.  Consequently, it's not easy to avoid the appearance of math markup in the table).  \r\n\r\n"""
,,,,,,,,,,,,,,
,,,,,,,,,,,,,,
,,,,,,,,,,,,,,
,,,,,,,,,,,,,,
pydata/pandas#5221,20977929,jorisvandenbossche,jorisvandenbossche,2013-10-14 19:53:53,2014-02-24 12:56:13,2014-02-24 12:56:13,closed,,0.14.0,20,2/3 Compat;Docs,https://api.github.com/repos/pydata/pandas/issues/5221,b'DOC: use Sphinx extension directly from numpy/ipython instead of maintaining our own version',"b""Summary: proposal to not maintain our own version of Sphinx extension in pandas repo but instead use the extensions directly from the project it maintains.\r\n\r\nThe pandas docs are using some Sphinx extensions that are not included in Sphinx itself: `numpydoc` and ipythons `ipython_directive` and `ipython_console_highlighting` (also matplotlibs `plot_directive` is imported in conf.py, but this is not included in the pandas repo). \r\nThese extension are located here: https://github.com/pydata/pandas/tree/master/doc/sphinxext.\r\n\r\nI think that ideally pandas does not have to care about them, but just uses them by importing the extension from the respective project it lives under (numpy/ipython). \r\nSome recent issue with the doc building also arised form outdated versions of these extensions in pandas repo (see part of the commits in PR #5160 and #4165).\r\n\r\nThe original extensions are living here:\r\n\r\n- ipython sphinxext in ipython itself: https://github.com/ipython/ipython/tree/master/IPython/sphinxext\r\n- numpydoc in its own repo: https://github.com/numpy/numpydoc\r\n\r\n**Options** we could do:\r\n- ipython extensions can just be imported from there in conf.py (because ipython is already a dependency)\r\n- numpydoc could be added as a submodule (this is how eg numpy itself does it: https://github.com/numpy/numpy/tree/master/doc, 'sphinxext' links to numpydoc), or it can be added as a doc build dependency.\r\n\r\nPossible **problems** with this is that the version in the pandas repo has converged from the version in numpy/ipython:\r\n- I think for `numpydoc` this will not be a problem. Following the history it was updated 3 years ago, and then only recently for python 3 compatibility.\r\n- For `ipython_directive` this seems more of a problem, looking at the history: https://github.com/pydata/pandas/commits/master/doc/sphinxext/ipython_directive.py there seems to be work done on this specifically for the pandas docs. If this is the case that is has converged from the ipython one, then ideally this could be contributed back to ipython (if the feature is not available there), but this will be more work to adapt.\r\n"""
pydata/pandas#5925,25516309,y-p,y-p,2014-01-13 18:15:06,2014-06-16 03:52:02,2014-01-18 16:30:29,closed,,0.13.1,12,,https://api.github.com/repos/pydata/pandas/issues/5925,b'Rebase ipython_directive on top of recent ipython updated version',"b""https://github.com/ipython/ipython/pull/4570\r\n\r\nWe'd prefer to get rid of the duplication, but we have some tweaks in place\r\nwhich ipython does not.\r\n\r\nI rebased everythingon top of ipython to generae a clean diff, if they pick it up\r\nwe can make the transition, otherwise we synched for now.\r\n\r\ncc @takluyver, if you're interested, check the diff between  \t2e3c608 and  \t82b8c3a\r\nfor an unobstructed view.\r\n\r\n@jorisvandenbossche, can you check this out and let me know if I missed anything?\r\nI included the cython magic fixes you pointed out.\r\n\r\nrelated https://github.com/pydata/pandas/issues/5221"""
swcarpentry/bc#163,23145337,gvwilson,gvwilson,2013-11-22 15:36:51,2014-07-17 01:31:32,2013-11-22 17:49:56,closed,,,20,,https://api.github.com/repos/swcarpentry/bc/issues/163,"b'Trying to teach nbconvert to make pages from our notebooks, but tripping over Unicode characters'","b'The Makefile is trying to do the right thing, but characters like `&times;` in the HTML get converted to u\'\\xd7\', which then produce the stack trace below. If anyone knows the magic words, please let me know.  (Storing the `\xa1\xc1` character directly in the notebook doesn\'t work either.)\r\n\r\n```\r\nTraceback (most recent call last):\r\n  File ""/Users/gwilson/anaconda/bin/ipython"", line 6, in <module>\r\n    sys.exit(start_ipython())\r\n  File ""/Users/gwilson/anaconda/lib/python2.7/site-packages/IPython/__init__.py"", line 118, in start_ipython\r\n    return launch_new_instance(argv=argv, **kwargs)\r\n  File ""/Users/gwilson/anaconda/lib/python2.7/site-packages/IPython/config/application.py"", line 539, in launch_instance\r\n    app.start()\r\n  File ""/Users/gwilson/anaconda/lib/python2.7/site-packages/IPython/terminal/ipapp.py"", line 356, in start\r\n    return self.subapp.start()\r\n  File ""/Users/gwilson/anaconda/lib/python2.7/site-packages/IPython/nbconvert/nbconvertapp.py"", line 266, in start\r\n    self.convert_notebooks()\r\n  File ""/Users/gwilson/anaconda/lib/python2.7/site-packages/IPython/nbconvert/nbconvertapp.py"", line 305, in convert_notebooks\r\n    write_resultes = self.writer.write(output, resources, notebook_name=notebook_name)\r\n  File ""/Users/gwilson/anaconda/lib/python2.7/site-packages/IPython/nbconvert/writers/stdout.py"", line 34, in write\r\n    print(output)\r\nUnicodeEncodeError: \'ascii\' codec can\'t encode character u\'\\xd7\' in position 212734: ordinal not in range(128)\r\n```'"
JuliaLang/julia#6225,29838155,stevengj,jakebolewski,2014-03-20 17:13:59,2015-08-11 22:13:55,2015-08-11 22:13:55,closed,,,8,REPL,https://api.github.com/repos/JuliaLang/julia/issues/6225,b'REPL semicolon output suppression is borked',"b'As @StefanKarpinski remarked in JuliaLang/IJulia.jl#160, the REPL currently does:\r\n```julia\r\njulia> 1; #=# 2\r\n\r\njulia> ans\r\n2\r\n```\r\nBoth IJulia and the REPL use a simplistic heuristic for suppressing output, but I think IJulia\'s `ismatch(r"";\\s*$"", code)` may be better here (even if it fails to suppress output from `1; #`).\r\n\r\nIn principle, there is probably some way to get the Julia parser to tell us if input ended with a semicolon, and e.g. have `include_string` return `nothing` in that case, but it may be tricky because I don\'t think we want `x;` to parse to a semantically different expression than `x`.\r\n\r\ncc: @loladiro, JuliaLang/IJulia.jl#109'"
enthought/distarray#51,20435913,bgrant,kwmsmith,2013-10-03 03:45:04,2015-10-12 22:10:23,2014-06-04 17:13:26,closed,,wishlist,7,,https://api.github.com/repos/enthought/distarray/issues/51,"b""Use `sync_imports` for local imports when it's fixed in IPython Parallel""",b'IPython issue:\r\n\r\nhttps://github.com/ipython/ipython/issues/4296'
jupyter/nbconvert#78,98458449,damianavila,,2015-07-31 19:44:52,2015-11-01 02:04:51,None,open,,,4,,https://api.github.com/repos/jupyter/nbconvert/issues/78,b'Review the scroll functionality in the slideshow',"b'@bollwyvl has raised a lot of concern about this and I agree with most of them, I think we should revisit our previous decision to have scrolling slides or make something like a `long slide` for people interested in that option.\r\n\r\nCheck @bollwyvl \'s points below:\r\n\r\nI think the phrase I used before was that they ""break the medium""... slides ""unintentionally"" bigger (i.e. not infinite like prezi, etc.) than the screen...\r\n- are not supported on any other slide platform\r\n- magnify the ""i\'m going to read you this slide"" presentation style... most people can read well north of 300 words per minute in their mother tongue, and showing someone a dense slide, they\'ll likely tune you out until they\'ve read it\r\n- break URLs: no way to link to a particular scrolled location. not that the reveal ones are great to begin with\r\n- are not liked by reveal, hence all our troubles\r\n  - will likely never printable or exportable, one of the use cases i value a lot but haven\'t been able to handle succinctly... even without scrolling slides... but at least it is theoretically doable!\r\n- which require a scroll wheel/bar during a talk is distracting to the speaker and the listeners, and content will be in a half-revealed state, which again breaks focus for both parties\r\n  - if the content really is big, like a big diagram or visualization, then temporary full screen/scroll/zoom on that content is a better fit... with text and margins so big, it\'s hard to even get 80 character code on a screen\r\n- break touch gestures (unless you\'ve fixed that!)\r\n\r\nperhaps an explicit longslide slidetype that, if found, would enable the scrolling, while slide would conform to the reveal model would be less surprising.'"
,,,,,,,,,,,,,,
,,,,,,,,,,,,,,
,,,,,,,,,,,,,,
,,,,,,,,,,,,,,
,,,,,,,,,,,,,,
,,,,,,,,,,,,,,
Homebrew/homebrew-python#23,12027806,samueljohn,samueljohn,2013-03-14 16:56:11,2013-12-28 12:17:13,2013-10-17 18:38:05,closed,,,10,new formula request;upstream,https://api.github.com/repos/Homebrew/homebrew-python/issues/23,b'New formula for ipython',"b'When setting up my python 2/3 installation, I found that `pip3 install ipython` does install `ipython3` that still uses 2.x syntax:\r\n\r\n```\r\nTraceback (most recent call last):\r\n[...]\r\n  File ""/homebrew/lib/python3.3/site-packages/IPython/config/application.py"", line 242\r\n    print os.linesep.join(lines)\r\n           ^\r\nSyntaxError: invalid syntax\r\n```\r\n\r\nWas the `2to3` run forgotten? I don\'t know. The `pip install ipython` for 2.x is fine!\r\n\r\nBut then I read (and was kind of shocked) that http://ipython.org/ipython-doc/stable/install/install.html tells us to use `easy_install` and `enpkg` (the enthought package manager).\r\n\r\nI think we can do better with homebrew, because all the deps are already in homebrew.'"
BhallaLab/moose#111,102502741,subhacom,dilawar,2013-04-10 06:15:03,2016-03-29 04:39:21,2016-03-29 04:39:21,closed,subhacom,,2,,https://api.github.com/repos/BhallaLab/moose/issues/111,b'Features/cleanup for multiscaleGui',"b'1. When gui is opened, there is message\r\nvoid DBusMenuExporterPrivate::addAction(QAction*, int): Already tracking action ""Python"" under id 10\r\nThis is something to do with ubuntu12.04,seems to occur when register the same action in the menu multiple times (https://github.com/ipython/ipython/issues/2988)\r\n2.Need to add Objecteditor\r\n3.Menu\'s order messup not sure what is the cause\r\n4.Need to implement plot view, When clicked on View->plotView\r\n  File ""/home/harsha/BuildQ/gui/mplugin.py"", line 115, in getPlotView\r\n    raise NotImplementedError(\'method must be implemented in derived class\')\r\nNotImplementedError: method must be implemented in derived class\r\n5.Height of scheduling window need to be fix (view->Run View) as it pushes entire gui to length greater than screen size.\r\n6.Should we not put a toggle button for all the ticks (may be for advance user)\r\n7.Need to set Run time from model (For kkit model, run time should be taken from kkit file otherise default)\r\n8.Need to check for ticks values for signalling model as compared to kkit file\r\n9.There is some kind of mis match with run the simulation v/s updating the plot graph, need closeup check on that.\r\n10.Unless model is loaded plot view or scheduling window should not come up?\n\nReported by: hrani'"
blink1073/oct2py#4,9592254,klonuo,blink1073,2012-12-31 12:31:16,2013-01-05 11:03:11,2013-01-05 11:03:11,closed,blink1073,,3,bug,https://api.github.com/repos/blink1073/oct2py/issues/4,b'Octavemagic fails to deliver inline images in IPython (on Windows)',b'I have necessary programs that output correctly for example `print -depsc` or `print -dsvg` ... from within Octave.\r\n\r\nIPython extension works fine except for drawing inline images as shown in their [example notebook file]( http://nbviewer.ipython.org/urls/raw.github.com/ipython/ipython/master/docs/examples/notebooks/octavemagic_extension.ipynb)\r\n\r\nProblem seems to be backslashes in created temp file. For example if my temp folder is `c:\\temp` octavemagic instructs octave/ghostscript to output file with this kind of path: \r\n\r\n` ... -OutputFile=c:        emp        mplaf_rm/__ipy_oct_fig_001.png c:\\temp\\oct-35.eps`\r\n\r\nwhere obviously backslash follow by `t` is passed as tab.'
spyder-ide/spyder#1082,57952581,spyder-issues-migrator,spyder-issues-migrator,2015-02-17 17:14:38,2015-02-17 17:14:42,2015-02-17 17:14:42,closed,,v2.3,5,1 star;Comp-Console-IPython;Type-Bug,https://api.github.com/repos/spyder-ide/spyder/issues/1082,b'IPython console: multiprocessing print output goes to kernel not client',"b'_From [r.lup...@gmail.com](https://code.google.com/u/105767089042807008718/) on 2012-06-06T06:29:47Z_\n\nSpyder Version:  2.2.0dev (2162: re67793ec2995 )\r\nPython Version:  2.7.2\r\nQt Version:      4.7.3, PyQt4 (API v2) 4.8.5 on Windows \n\nWhat steps will reproduce the problem?\n\n Normally standard output from scripts correctly ends up in the IPython console.\r\n\r\nUsing the multiprocessing module, standard output from subprocesses instead ends up in the kernel (external console) window.\r\n\r\nFor example, with the script below, ""Starting"" is printed to the IPython console, while the ""hello world""s appear in the kernel window.\r\n\r\n\\-------------------\r\nfrom multiprocessing import Process, Lock\r\n\r\ndef f(l, i):\r\n    l.acquire()\r\n    print \'hello world\', i\r\n    l.release()\r\n\r\nif __name__ == \'__main__\':\r\n    print ""Starting""\r\n    lock = Lock()\r\n    for num in range(10):\r\n        Process(target=f, args=(lock, num)).start()\n\n_Original issue: http://code.google.com/p/spyderlib/issues/detail?id=1082_'"
claesenm/optunity#8,38398622,claesenm,claesenm,2014-07-22 13:17:26,2015-07-10 08:57:56,2015-07-10 08:57:56,closed,,,4,bug;wontfix,https://api.github.com/repos/claesenm/optunity/issues/8,b'IPython crashes with optunity.parallel.pmap',"b""IPython crashes if the parallelized function outputs anything to stdout or stderr. This is an IPython issue that we can't fix ourselves. \r\n\r\nMore info at: https://github.com/ipython/ipython/issues/2438/\r\n\r\nA workaround is to use IPython's own parallel features:\r\nhttp://nbviewer.ipython.org/github/vals/scilife-python-course/blob/master/parallel%20python.ipynb"""
matplotlib/matplotlib#1126,6350805,taldcroft,mdboom,2012-08-21 13:54:30,2013-11-30 19:25:13,2013-02-11 17:48:57,closed,,1.2.x known bugs,12,,https://api.github.com/repos/matplotlib/matplotlib/issues/1126,b'Qt4 save dialog not functional on CentOS-5',"b""After opening a plot window using the Qt4 backend and then trying to save the plot using the plot window Save button, a file dialog window appears for just a flash and then disappears.  All other window functionality works as expected.\n\n@fheday earlier reported seeing the same behaviour in macos x Lion (Python 2.7.2, matplotlib 1.1.0, Qt 4.7.4+quartz, macports) in issue #238.\n\nI'm running on linux x64_64 with CentOS-5, using ActiveState Python and Qt4 / PyQt4 built from source.\n\n```\nbasedirlist is: ['/usr/local', '/usr']\n============================================================================\nBUILDING MATPLOTLIB\n            matplotlib: 1.2.x\n                python: 2.7.1 (r271:86832, Feb  7 2011, 11:30:54)  [GCC\n                        4.0.2 20051125 (Red Hat 4.0.2-8)]\n              platform: linux2\n\nREQUIRED DEPENDENCIES\n                 numpy: 1.6.2\n             freetype2: 9.10.3\n\nOPTIONAL BACKEND DEPENDENCIES\n                libpng: 1.2.10\n               Tkinter: Tkinter: 81008, Tk: 8.5, Tcl: 8.5\n                        * Guessing the library and include directories for\n                        * Tcl and Tk because the tclConfig.sh and\n                        * tkConfig.sh could not be found and/or parsed.\n                  Gtk+: gtk+: 2.18.3, glib: 2.22.2, pygtk: 2.16.0,\n                        pygobject: 2.20.0\n       Mac OS X native: no\n                    Qt: no\n                   Qt4: Qt: 4.8.0, PyQt4: 4.9\n                PySide: no\n                 Cairo: 1.8.8\n\nOPTIONAL DATE/TIMEZONE DEPENDENCIES\n              datetime: present, version unknown\n              dateutil: 1.5\n                  pytz: 2010o\n\nOPTIONAL USETEX DEPENDENCIES\n                dvipng: 1.5\n           ghostscript: 8.70\n                 latex: 3.141592\n               pdftops: 3.00\n```"""
Linuxbrew/legacy-linuxbrew#1071,148099548,tulindanil,,2016-04-13 15:32:04,2016-05-04 16:20:11,None,open,sjackman,,28,bug,https://api.github.com/repos/Linuxbrew/legacy-linuxbrew/issues/1071,"b""git: error: unknown option `no-edit' or `config` or `local`""","b""I have git 1.7.1 \r\nI try to \r\n\r\n```sh\r\n$ brew install python3\r\n==> Tapping homebrew/dupes\r\nerror: unknown option `config\r\n```\r\nor \r\n```sh\r\n$ brew update\r\nerror: unknown option `no-edit'\r\n```\r\n\r\nThat mistakes about the age of my git's version, but I can't find out what version is better to use\r\nUnder some circumstances I can't use cutting-edge 2.* versions :("""
neo4j/neo4j#273,8289928,lassewesth,jakewins,2012-11-12 14:03:17,2014-11-11 23:15:07,2014-11-11 23:15:07,closed,,,2,,https://api.github.com/repos/neo4j/neo4j/issues/273,b'importing neo4j breaks Control-C signal handler',"b""@shawnlower: 'Hi,\r\n\r\nAfter importing neo4j, pressing Control-C causes the interactive Python shell (CPython or ipython) to abruptly abort with no error, and without properly resetting the terminal.\r\n\r\nWhen testing code, it's normal to use Control-C to return to the python shell, without evaluating the current line / code block. Getting kicked back to a shell and losing all of your state gets pretty frustrating, and as a common reflex, not pressing Control-C as usual is a hard habit to break.\r\n\r\nThis had originally been posted as an iPython bug here:\r\nhttps://github.com/ipython/ipython/issues/2188\r\n\r\n#########################################################################\r\n### Crashy behavior:\r\n\r\n```python\r\nshawn@carbon:~/Download/neo4j-community-1.8$ ipython\r\n\r\nIn [1]: from neo4j import GraphDatabase\r\n\r\nIn [2]: shawn@carbon:~/Download/neo4j-community-1.8$ 130\r\nshawn@carbon:~/Download/neo4j-community-1.8$ shawn@carbon:~/Download/neo4j-community-1.8$ \r\nshawn@carbon:~/Download/neo4j-community-1.8$ \r\n```\r\n\r\n#########################################################################\r\n\r\nControl-C was pressed at [2]. Afterward I ran 'echo $?', to show the return code of 130, and 'stty echo' to fix the terminal ('reset' would also work).\r\n\r\n#########################################################################\r\n### Workaround:\r\n\r\n```python\r\nshawn@carbon:~/Download/neo4j-community-1.8$ ipython\r\n\r\nIn [1]: from neo4j import GraphDatabase\r\n\r\nIn [2]: import signal\r\n\r\nIn [3]: signal.signal(signal.SIGINT, signal.default_int_handler)\r\nOut[3]: <function signal.default_int_handler>\r\n\r\nIn [4]: \r\nKeyboardInterrupt\r\n\r\nIn [4]: \r\n```\r\n\r\n#########################################################################\r\n\r\nFor reference, here are a few of the other package versions:\r\n\r\n- neo4j-community-1.8\r\n- JPype==0.5.4.2 (via pip)\r\n- openjdk-6-jre-headless 6b24-1.11.4-1ubuntu0.12.04.1 i386\r\n'"""
sagemath/sagecell#433,24163120,jasongrout,,2013-12-12 08:17:41,2013-12-12 08:17:41,None,open,,,0,,https://api.github.com/repos/sagemath/sagecell/issues/433,b'graphics with NaN throw a json error',"b""This is because json doesn't actually support NaN:\r\n\r\nhttps://github.com/ipython/ipython/issues/2187/\r\n\r\nhttp://stackoverflow.com/questions/6601812/sending-nan-in-json\r\n\r\nWe could clean the NaN out of the json, we could throw an error by setting allow_nan to false, or we could just use the IPython json cleaning function."""
praw-dev/praw#485,97972923,RGood,bboe,2015-07-29 16:15:22,2015-08-23 21:04:35,2015-08-23 21:04:35,closed,,,4,,https://api.github.com/repos/praw-dev/praw/issues/485,b'login() function returning error when given no params',"b'Whenever the .login() function was called without being passed parameters, it would prompt the user for them. When done now the code throws an exception\r\n\r\n    >>> r.login()\r\n    Username: The1RGood\r\n    Traceback (most recent call last):\r\n      File ""<stdin>"", line 1, in <module>\r\n      File ""<string>"", line 2, in login\r\n      File ""C:\\python27\\lib\\site-packages\\praw-3.1.0-py2.7.egg\\praw\\decorators.py"", line 75, in wrap\r\n        return function(*args, **kwargs)\r\n       File ""C:\\python27\\lib\\site-packages\\praw-3.1.0-py2.7.egg\\praw\\__init__.py"", line 1390, in login\r\n        pswd = getpass.getpass(\'Password for %s: \' % user)\r\n      File ""C:\\python27\\lib\\getpass.py"", line 95, in win_getpass\r\n        msvcrt.putch(c)\r\n    TypeError: must be char, not unicode'"
edx/edx-platform#3170,30680233,valera-rozuvan,valera-rozuvan,2014-04-02 11:39:03,2015-02-17 20:39:37,2014-04-02 20:18:52,closed,,,6,,https://api.github.com/repos/edx/edx-platform/issues/3170,b'Remove a method call which depends on IPython.',"b'**Description**\r\n\r\nBecause IPython is not part of edx-platform dependencies, the method `assert_in` has to be defined.\r\n\r\n**Reviewers**\r\n\r\n- @auraz '"
,,,,,,,,,,,,,,
pydata/pandas#960,3783871,dfarmer,adamklein,2012-03-23 17:32:20,2014-03-26 19:30:29,2012-03-23 19:39:09,closed,,,2,,https://api.github.com/repos/pydata/pandas/issues/960,b'reindex kills IPython',"b""I'm running pandas 0.7.2 and IPython 0.12, the following toy example reproduces the behavior on my machine 100% of the time. \r\n\r\n``` python\r\ndf = pandas.DataFrame({'A' : ['foo', 'bar', 'foo', 'bar',\r\n                      'foo', 'bar', 'foo', 'foo'],\r\n                  'B' : ['one', 'one', 'two', 'three',\r\n                        'two', 'two', 'one', 'three'],\r\n                   'C' : randn(8), 'D' : randn(8)})\r\ndf\r\ngrp = df.groupby('A')\r\ntstgrp = grp.get_group('foo')\r\n```\r\n....\r\nNow typing \r\n    tstgrp.reindex( \r\n\r\ncrashes the IPython kernel. I am actually guessing this is an IPython bug, but I know that Pandas does hook in to IPython so I figured I'd start here."""
jupyter/qtconsole#76,122635816,dashesy,,2015-12-17 00:35:17,2016-03-07 17:21:04,None,open,,4.3,8,,https://api.github.com/repos/jupyter/qtconsole/issues/76,"b'After a kernel reset, input line hangs'","b""Windows with Jupyter QtConsole 4.1.1 but I have seen this on Linux on iPython too.\r\n\r\n* Add these lines to `ipython_config.py`, because I want `pylab` mode and `autoreload` for my development.\r\n\r\n```python\r\n    c.InteractiveShellApp.extensions = ['autoreload', 'pylab']\r\n    c.InteractiveShellApp.exec_lines = ['%autoreload 2', '%pylab']\r\n```\r\n\r\n* Then use <kbd>ctrl</kbd>+<kbd>.</kbd> to reset the kernel.\r\n\r\nIf I am running `QtConsole` for some time, sometimes the input hangs. I will have to close the application and open it again. \r\n\r\nThis is not a big issue, but wanted to see if I am alone in seeing this problem and if there is any workaround, or if I could help debugging this. \r\n"""
jupyter/qtconsole#94,129820791,taerath,,2016-01-29 16:46:32,2016-07-14 22:00:18,None,open,,4.3,5,bug,https://api.github.com/repos/jupyter/qtconsole/issues/94,"b'Occasionally, Qtconse stops responding to some keystrokes'","b""I am using Jupyter QtConsole 4.1.1 from Continuum's Anaconda. \r\n\r\nEvery once in a while, the Qtconsole windows stops accepting some keystrokes. I can still enter most characters and numbers, but if I press e.g. return or backspace, nothing happens.\r\n\r\nSometimes I can get things to work again by either:\r\n* Opening a new tab (and then switching back to the old one)\r\n* Pressing Ctrl-p or Ctrl-y repeatedly\r\n\r\nIs there anything I can do to debug this further?"""
JuliaLang/IJulia.jl#409,136799808,SoYman,stevengj,2016-02-26 20:03:48,2016-02-26 20:34:50,2016-02-26 20:34:50,closed,,,1,,https://api.github.com/repos/JuliaLang/IJulia.jl/issues/409,"b""MathJax doesn't render higher order roots ""","b""I'm not sure if I this is specific to IJulia or more generally Jupyter or MathJax but when the HTML-CSS renderer tries to display a cube root, for example, the output is simply: \\root{3}{x} with no pretty printing."""
mathjax/MathJax#71,592599,slymz,dpvc,2011-02-11 19:16:07,2012-12-19 17:44:20,2012-02-27 15:41:39,closed,,,27,Fixed;Test Available;v2.0,https://api.github.com/repos/mathjax/MathJax/issues/71,b'equation \\label and \\ref',"b""Feature request!  Can we have \\label and \\ref facilities for equations?\r\n\r\nThis may be a popular one indeed, but I couldn't find it on issue list (or mention of it in the documentation). And is basically been discussed long back: http://sourceforge.net/projects/mathjax/forums/forum/948700/topic/3817124\r\n\r\nThank you!\r\n\r\n"""
NSLS-II/bluesky#309,130026735,ambarb,danielballan,2016-01-30 19:21:54,2016-02-01 04:10:06,None,open,,,10,,https://api.github.com/repos/NSLS-II/bluesky/issues/309,b'reverse search and cancel issue',"b'Reverse search and cancel (^C) does not clean up properly.  Somehow the command is held in memory and the search result is still executed (it is not displayed on the next line). Two examples are below.  In the second, multiple ^Cs after the initial canel still results in search result execution. In followed by multiple ^C to create new lines does not clean up properly. In this last example, access at the beamline was removed from EPU2 (as it is the other branch\'s EPU) which is what is responsible for all the errors.  \r\n\r\n```python\r\nn [23]: \r\n\r\nIn [23]: \r\n\r\nIn [23]: mov(pgm_en,459.50)\r\n\r\n   pgm_en             \r\n\r\n    459.447305        \r\n\r\n\r\n(reverse-i-search)`ep\': wh_pos(epu2)\r\nKeyboardInterrupt\r\n\r\nIn [24]: wh_pos(epu2)\r\n\r\n+------------+----------+-----------+------------+\r\n| Positioner |    Value | Low Limit | High Limit |\r\n+------------+----------+-----------+------------+\r\n| epu2_phase |  0.00023 | -24.60000 |   24.60000 |\r\n| epu2_gap   | 21.96699 |  12.00000 |  239.00000 |\r\n+------------+----------+-----------+------------+\r\n\r\n(reverse-i-search)`epu1\': ascan(epu1.gap,80.8,81.6,30)\r\nKeyboardInterrupt\r\n\r\nIn [25]: \r\nKeyboardInterrupt\r\n\r\nIn [25]: \r\nKeyboardInterrupt\r\n\r\nIn [25]: \r\nKeyboardInterrupt\r\n\r\nIn [25]: \r\nKeyboardInterrupt\r\n\r\nIn [25]: ascan(epu1.gap,80.8,81.6,30)\r\nTransient Scan ID: 56899\r\nPersistent Unique Scan ID: \'056bd6d5-b6e6-4df8-b079-602dd7000539\'\r\n+------------+--------------+---------------------+---------------------+------------------------+----------------+\r\n|   seq_num  |        time  |  epu1_gap_readback  |  epu1_gap_setpoint  |  epu1_gap_stop_signal  |      sclr_ch2  |\r\n+------------+--------------+---------------------+---------------------+------------------------+----------------+\r\nRun aborted\r\n put returned \'Write access denied\'\r\n/home/xf23id1/conda_envs/collection/lib/python3.4/site-packages/numpy/core/_methods.py:59: RuntimeWarning: Mean of empty slice.\r\n  warnings.warn(""Mean of empty slice."", RuntimeWarning)\r\n+------------+--------------+---------------------+---------------------+------------------------+----------------+\r\n/home/xf23id1/conda_envs/collection/lib/python3.4/site-packages/bluesky/run_engine.py:1180: UserWarning: A ValueError(\'attempt to get argmax of an empty sequence\',) was raised during the processing of a stop Document. The error will be ingored to avoid interrupting data collection. To investigate, set RunEngine.ignore_callback_exceptions = False and run again.\r\n  ""and run again."" % (exc, name.name))\r\n---------------------------------------------------------------------------\r\nCASeverityException                       Traceback (most recent call last)\r\n<ipython-input-25-11629fed1a54> in <module>()\r\n----> 1 ascan(epu1.gap,80.8,81.6,30)\r\n\r\n/home/xf23id1/conda_envs/collection/lib/python3.4/site-packages/bluesky/simple_scans.py in __call__(self, motor, start, finish, intervals, time, subs, **kwargs)\r\n    254         original_times = _set_acquire_time(time)\r\n    255         result = super().__call__(motor, start, finish, intervals + 1,\r\n--> 256                                   subs=subs, **kwargs)\r\n    257         _unset_acquire_time(original_times)\r\n    258         return result\r\n\r\n/home/xf23id1/conda_envs/collection/lib/python3.4/site-packages/bluesky/simple_scans.py in __call__(self, subs, sub_factories, *args, **kwargs)\r\n    150         # Any remainging kwargs go the RE. To be safe, no args are passed\r\n    151         # to RE; RE args effectively become keyword-only arguments.\r\n--> 152         return gs.RE(self.scan, _subs, **kwargs)\r\n    153 \r\n    154 \r\n\r\n/home/xf23id1/conda_envs/collection/lib/python3.4/site-packages/bluesky/run_engine.py in __call__(self, plan, subs, **metadata_kw)\r\n    529                 exc = self._task.exception()\r\n    530                 if exc is not None:\r\n--> 531                     raise exc\r\n    532 \r\n    533         return self._run_start_uids\r\n\r\n/home/xf23id1/conda_envs/collection/lib/python3.4/asyncio/tasks.py in _step(***failed resolving arguments***)\r\n    237                 # We use the `send` method directly, because coroutines\r\n    238                 # don\'t have `__iter__` and `__next__` methods.\r\n--> 239                 result = coro.send(None)\r\n    240             else:\r\n    241                 result = coro.throw(exc)\r\n\r\n/home/xf23id1/conda_envs/collection/lib/python3.4/site-packages/bluesky/run_engine.py in _run(self)\r\n    700             logger.error(""Run aborted"")\r\n    701             logger.error(""%s"", err)\r\n--> 702             raise err\r\n    703         finally:\r\n    704             self.state = \'idle\'\r\n\r\n/home/xf23id1/conda_envs/collection/lib/python3.4/site-packages/bluesky/run_engine.py in _run(self)\r\n    673                         raise\r\n    674                     except Exception as e:\r\n--> 675                         self._genstack[-1].throw(e)\r\n    676                     self.debug(\'RE.state: \' + self.state)\r\n    677                     self.debug(\'msg: {}\\n  response: {}\'.format(msg, response))\r\n\r\n/home/xf23id1/conda_envs/collection/lib/python3.4/site-packages/bluesky/plans.py in __iter__(self)\r\n     75             yield Msg(\'kickoff\', flyer, block_group=\'_flyers\')\r\n     76             yield Msg(\'wait\', None, \'_flyers\')\r\n---> 77         yield from self._gen()\r\n     78         for flyer in self.flyers:\r\n     79             yield Msg(\'collect\', flyer, block_group=\'_flyers\')\r\n\r\n/home/xf23id1/conda_envs/collection/lib/python3.4/site-packages/bluesky/plans.py in _gen(self)\r\n    187         for step in self._abs_steps:\r\n    188             yield Msg(\'checkpoint\')\r\n--> 189             yield Msg(\'set\', self.motor, step, block_group=\'A\')\r\n    190             yield Msg(\'wait\', None, \'A\')\r\n    191             yield Msg(\'create\')\r\n\r\n/home/xf23id1/conda_envs/collection/lib/python3.4/site-packages/bluesky/run_engine.py in _run(self)\r\n    669                         self.debug(""About to process: {0}, {1}"".\r\n    670                                    format(coro, msg))\r\n--> 671                         response = yield from coro(msg)\r\n    672                     except KeyboardInterrupt:\r\n    673                         raise\r\n\r\n/home/xf23id1/conda_envs/collection/lib/python3.4/asyncio/coroutines.py in coro(*args, **kw)\r\n    204         @functools.wraps(func)\r\n    205         def coro(*args, **kw):\r\n--> 206             res = func(*args, **kw)\r\n    207             if isinstance(res, futures.Future) or inspect.isgenerator(res):\r\n    208                 res = yield from res\r\n\r\n/home/xf23id1/conda_envs/collection/lib/python3.4/site-packages/bluesky/run_engine.py in _set(self, msg)\r\n   1003         block_group = msg.kwargs.pop(\'block_group\', None)\r\n   1004         self._movable_objs_touched.add(msg.obj)\r\n-> 1005         ret = msg.obj.set(*msg.args, **msg.kwargs)\r\n   1006         if block_group:\r\n   1007             p_event = asyncio.Event()\r\n\r\n/home/xf23id1/conda_envs/collection/lib/python3.4/site-packages/ophyd/positioner.py in set(self, new_position, wait, moved_cb, timeout)\r\n    189         """"""\r\n    190         return self.move(new_position, wait=wait, moved_cb=moved_cb,\r\n--> 191                          timeout=timeout)\r\n    192 \r\n    193     def _repr_info(self):\r\n\r\n/home/xf23id1/conda_envs/collection/lib/python3.4/site-packages/ophyd/pv_positioner.py in move(self, position, wait, **kwargs)\r\n    176                 ret = super().move(position, wait=False, **kwargs)\r\n    177                 self._started_moving = False\r\n--> 178                 self._move_async(position, **kwargs)\r\n    179                 return ret\r\n    180         except KeyboardInterrupt:\r\n\r\n/home/xf23id1/conda_envs/collection/lib/python3.4/site-packages/ophyd/pv_positioner.py in _move_async(self, position, **kwargs)\r\n    295         else:\r\n    296             self.setpoint.put(position, wait=False,\r\n--> 297                               callback=done_moving)\r\n\r\n/home/xf23id1/conda_envs/collection/lib/python3.4/site-packages/ophyd/signal.py in put(self, value, force, **kwargs)\r\n    531 \r\n    532         self._write_pv.put(value, use_complete=use_complete,\r\n--> 533                            **kwargs)\r\n    534 \r\n    535         old_value = self._setpoint\r\n\r\n/home/xf23id1/conda_envs/collection/lib/python3.4/site-packages/epics/pv.py in put(self, value, wait, timeout, use_complete, callback, callback_data)\r\n    337                       wait=wait, timeout=timeout,\r\n    338                       callback=callback,\r\n--> 339                       callback_data=callback_data)\r\n    340 \r\n    341     def __putCallbackStub(self, pvname=None, **kws):\r\n\r\n/home/xf23id1/conda_envs/collection/lib/python3.4/site-packages/epics/ca.py in wrapper(*args, **kwds)\r\n    403                                                         name(chid), timeout))\r\n    404 \r\n--> 405         return fcn(*args, **kwds)\r\n    406     wrapper.__doc__ = fcn.__doc__\r\n    407     wrapper.__name__ = fcn.__name__\r\n\r\n/home/xf23id1/conda_envs/collection/lib/python3.4/site-packages/epics/ca.py in put(chid, value, wait, timeout, callback, callback_data)\r\n   1353     ret = libca.ca_array_put_callback(ftype, count, chid,\r\n   1354                                       data, _CB_PUTWAIT, 0)\r\n-> 1355     PySEVCHK(\'put\', ret)\r\n   1356     poll(evt=1.e-4, iot=0.05)\r\n   1357     if wait:\r\n\r\n/home/xf23id1/conda_envs/collection/lib/python3.4/site-packages/epics/ca.py in PySEVCHK(func_name, status, expected)\r\n    432     if status == expected:\r\n    433         return status\r\n--> 434     raise CASeverityException(func_name, message(status))\r\n    435 \r\n    436 def withSEVCHK(fcn):\r\n\r\nCASeverityException:  put returned \'Write access denied\'\r\n\r\n```\r\n'"
sympy/sympy#8140,44271368,ClemensFMN,hargup,2014-09-29 09:00:24,2015-06-12 14:09:51,2015-06-12 14:09:51,closed,,,4,,https://api.github.com/repos/sympy/sympy/issues/8140,b'Plotting does not work with piecewise functions',"b""The following code yields an error (both 0.7.5 and git)\r\n\r\n    from sympy import *\r\n    from sympy.plotting import *\r\n    from sympy.stats import *\r\n\r\n    x = symbols('x')\r\n    fx = Piecewise( (1, x<1), (0, True))\r\n    plot(fx)\r\n\r\n\r\nError message is below. The issue came up in this discussion: https://groups.google.com/forum/?hl=de#!topic/sympy/rlNZIQLY5qk and seems to exist both in python 2.7 & python 3.\r\n\r\nError message\r\n\r\n---------------------------------------------------------------------------\r\nAttributeError                            Traceback (most recent call last)\r\n/usr/lib/python2.7/dist-packages/IPython/utils/py3compat.pyc in execfile(fname, *where)\r\n    202             else:\r\n    203                 filename = fname\r\n--> 204             __builtin__.execfile(filename, *where)\r\n\r\n/home/cnovak/Desktop/piecewise_simple.py in <module>()\r\n     15 \r\n     16 \r\n---> 17 plot(fx)\r\n\r\n/home/cnovak/sympy/sympy/plotting/plot.pyc in plot(*args, **kwargs)\r\n   1278     plots = Plot(*series, **kwargs)\r\n   1279     if show:\r\n-> 1280         plots.show()\r\n   1281     return plots\r\n   1282 \r\n\r\n/home/cnovak/sympy/sympy/plotting/plot.pyc in show(self)\r\n    183             self._backend.close()\r\n    184         self._backend = self.backend(self)\r\n--> 185         self._backend.show()\r\n    186 \r\n    187     def save(self, path):\r\n\r\n/home/cnovak/sympy/sympy/plotting/plot.pyc in show(self)\r\n   1016 \r\n   1017     def show(self):\r\n-> 1018         self.process_series()\r\n   1019         #TODO after fixing https://github.com/ipython/ipython/issues/1255\r\n   1020         # you can uncomment the next line and remove the pyplot.show() call\r\n\r\n/home/cnovak/sympy/sympy/plotting/plot.pyc in process_series(self)\r\n    895             # Create the collections\r\n    896             if s.is_2Dline:\r\n--> 897                 collection = self.LineCollection(s.get_segments())\r\n    898                 self.ax.add_collection(collection)\r\n    899             elif s.is_contour:\r\n\r\n/home/cnovak/sympy/sympy/plotting/plot.pyc in get_segments(self)\r\n    503             f_start = f(self.start)\r\n    504             f_end = f(self.end)\r\n--> 505             sample([self.start, f_start], [self.end, f_end], 0)\r\n    506             return list_segments\r\n    507 \r\n\r\n/home/cnovak/sympy/sympy/plotting/plot.pyc in sample(p, q, depth)\r\n    477                 #depth of 6. We are not using linspace to avoid aliasing.\r\n    478                 elif depth < 6:\r\n--> 479                     sample(p, new_point, depth + 1)\r\n    480                     sample(new_point, q, depth + 1)\r\n    481 \r\n\r\n/home/cnovak/sympy/sympy/plotting/plot.pyc in sample(p, q, depth)\r\n    477                 #depth of 6. We are not using linspace to avoid aliasing.\r\n    478                 elif depth < 6:\r\n--> 479                     sample(p, new_point, depth + 1)\r\n    480                     sample(new_point, q, depth + 1)\r\n    481 \r\n\r\n/home/cnovak/sympy/sympy/plotting/plot.pyc in sample(p, q, depth)\r\n    477                 #depth of 6. We are not using linspace to avoid aliasing.\r\n    478                 elif depth < 6:\r\n--> 479                     sample(p, new_point, depth + 1)\r\n    480                     sample(new_point, q, depth + 1)\r\n    481 \r\n\r\n/home/cnovak/sympy/sympy/plotting/plot.pyc in sample(p, q, depth)\r\n    477                 #depth of 6. We are not using linspace to avoid aliasing.\r\n    478                 elif depth < 6:\r\n--> 479                     sample(p, new_point, depth + 1)\r\n    480                     sample(new_point, q, depth + 1)\r\n    481 \r\n\r\n/home/cnovak/sympy/sympy/plotting/plot.pyc in sample(p, q, depth)\r\n    477                 #depth of 6. We are not using linspace to avoid aliasing.\r\n    478                 elif depth < 6:\r\n--> 479                     sample(p, new_point, depth + 1)\r\n    480                     sample(new_point, q, depth + 1)\r\n    481 \r\n\r\n/home/cnovak/sympy/sympy/plotting/plot.pyc in sample(p, q, depth)\r\n    477                 #depth of 6. We are not using linspace to avoid aliasing.\r\n    478                 elif depth < 6:\r\n--> 479                     sample(p, new_point, depth + 1)\r\n    480                     sample(new_point, q, depth + 1)\r\n    481 \r\n\r\n/home/cnovak/sympy/sympy/plotting/plot.pyc in sample(p, q, depth)\r\n    495                 #value) or the three points are not almost collinear.\r\n    496                 elif (p[1] is None or q[1] is None or new_point[1] is None\r\n--> 497                         or not flat(p, new_point, q)):\r\n    498                     sample(p, new_point, depth + 1)\r\n    499                     sample(new_point, q, depth + 1)\r\n\r\n/home/cnovak/sympy/sympy/plotting/plot.pyc in flat(x, y, z, eps)\r\n   1090     vector_b = z - y\r\n   1091     dot_product = np.dot(vector_a, vector_b)\r\n-> 1092     vector_a_norm = np.linalg.norm(vector_a)\r\n   1093     vector_b_norm = np.linalg.norm(vector_b)\r\n   1094     cos_theta = dot_product / (vector_a_norm * vector_b_norm)\r\n\r\n/usr/lib/python2.7/dist-packages/numpy/linalg/linalg.pyc in norm(x, ord, axis)\r\n   2054     # Check the default case first and handle it immediately.\r\n   2055     if ord is None and axis is None:\r\n-> 2056         return sqrt(add.reduce((x.conj() * x).real, axis=None))\r\n   2057 \r\n   2058     # Normalize the `axis` argument to a tuple.\r\n\r\nAttributeError: sqrt"""
inducer/pudb#30,2744262,asmeurer,asmeurer,2012-01-06 04:46:55,2012-01-11 14:44:34,2012-01-11 14:23:49,closed,,,14,,https://api.github.com/repos/inducer/pudb/issues/30,b'Problems with pudb and IPython 0.12',"b'I got this both in IPython 0.12 and the git master of IPython. If I type ! to go to IPython, I get the following.  The first few frames up to _print_Pow are my debugging stack.\r\n\r\n```py\r\nERROR: An unexpected error occurred while tokenizing input\r\nThe following traceback may be corrupted or invalid\r\nThe error message is: (\'EOF in multi-line statement\', (101, 0))\r\n---------------------------------------------------------------------------\r\nAttributeError                            Traceback (most recent call last)\r\n/Users/aaronmeurer/Documents/Python/sympy/sympy/<ipython-input-6-3a09c478a981> in <module>()\r\n----> 1 pprint(g)\r\n\r\n/Users/aaronmeurer/Documents/Python/sympy/sympy/sympy/printing/pretty/pretty.pyc in pretty_print(expr, **settings)\r\n   1402 \r\n   1403     """"""\r\n-> 1404     print pretty(expr, **settings)\r\n   1405 \r\n   1406 pprint = pretty_print\r\n\r\n/Users/aaronmeurer/Documents/Python/sympy/sympy/sympy/printing/pretty/pretty.pyc in pretty(expr, **settings)\r\n   1373 \r\n   1374     try:\r\n-> 1375         return pp.doprint(expr)\r\n   1376     finally:\r\n   1377         pretty_use_unicode(uflag)\r\n\r\n/Users/aaronmeurer/Documents/Python/sympy/sympy/sympy/printing/pretty/pretty.pyc in doprint(self, expr)\r\n     40 \r\n     41     def doprint(self, expr):\r\n---> 42         return self._print(expr).render(**self._settings)\r\n     43 \r\n     44     # empty op so _print(stringPict) returns the same\r\n\r\n\r\n/Users/aaronmeurer/Documents/Python/sympy/sympy/sympy/printing/printer.pyc in _print(self, expr, *args)\r\n    250                 printmethod = \'_print_\' + cls.__name__\r\n    251                 if hasattr(self, printmethod):\r\n--> 252                     return getattr(self, printmethod)(expr, *args)\r\n    253 \r\n    254             # Unknown object, fall back to the emptyPrinter.\r\n\r\n\r\n/Users/aaronmeurer/Documents/Python/sympy/sympy/sympy/printing/pretty/pretty.pyc in _print_Mul(self, product)\r\n   1014                 b[i] = prettyForm(*self._print(b[i]).parens())\r\n   1015             else:\r\n-> 1016                 b[i] = self._print(b[i])\r\n   1017 \r\n   1018         # Construct a pretty form\r\n\r\n\r\n/Users/aaronmeurer/Documents/Python/sympy/sympy/sympy/printing/printer.pyc in _print(self, expr, *args)\r\n    250                 printmethod = \'_print_\' + cls.__name__\r\n    251                 if hasattr(self, printmethod):\r\n--> 252                     return getattr(self, printmethod)(expr, *args)\r\n    253 \r\n    254             # Unknown object, fall back to the emptyPrinter.\r\n\r\n\r\n/Users/aaronmeurer/Documents/Python/sympy/sympy/sympy/printing/pretty/pretty.pyc in _print_Pow(self, power)\r\n   1028         # square roots, other roots or n-th roots\r\n\r\n   1029         #test for fraction 1/n or power x**-1\r\n\r\n-> 1030         if power.is_commutative:\r\n   1031             if (isinstance(power.exp, C.Rational) and power.exp.p==1 and power.exp.q !=1) or \\\r\n   1032                (   isinstance(power.exp, C.Pow) and\r\n\r\n/Users/aaronmeurer/Documents/Python/sympy/sympy/sympy/printing/pretty/pretty.pyc in _print_Pow(self, power)\r\n   1028         # square roots, other roots or n-th roots\r\n\r\n   1029         #test for fraction 1/n or power x**-1\r\n\r\n-> 1030         if power.is_commutative:\r\n   1031             if (isinstance(power.exp, C.Rational) and power.exp.p==1 and power.exp.q !=1) or \\\r\n   1032                (   isinstance(power.exp, C.Pow) and\r\n\r\n/sw/lib/python2.7/bdb.pyc in trace_dispatch(self, frame, event, arg)\r\n     46             return # None\r\n     47         if event == \'line\':\r\n---> 48             return self.dispatch_line(frame)\r\n     49         if event == \'call\':\r\n     50             return self.dispatch_call(frame, arg)\r\n\r\n/sw/lib/python2.7/bdb.pyc in dispatch_line(self, frame)\r\n     64     def dispatch_line(self, frame):\r\n     65         if self.stop_here(frame) or self.break_here(frame):\r\n---> 66             self.user_line(frame)\r\n     67             if self.quitting: raise BdbQuit\r\n     68         return self.trace_dispatch\r\n\r\n/Users/aaronmeurer/Documents/pudb/pudb/debugger.pyc in user_line(self, frame)\r\n    237         self.ui.update_breakpoints()\r\n    238 \r\n--> 239         self.interaction(frame)\r\n    240 \r\n    241     def user_return(self, frame, return_value):\r\n\r\n/Users/aaronmeurer/Documents/pudb/pudb/debugger.pyc in interaction(self, frame, exc_tuple)\r\n    206         self.set_frame_index(index)\r\n    207 \r\n--> 208         self.ui.call_with_ui(self.ui.interaction, exc_tuple)\r\n    209 \r\n    210     def get_stack_situation_id(self):\r\n\r\n/Users/aaronmeurer/Documents/pudb/pudb/debugger.pyc in call_with_ui(self, f, *args, **kwargs)\r\n   1240         self.show()\r\n   1241         try:\r\n-> 1242             return f(*args, **kwargs)\r\n   1243         finally:\r\n   1244             self.hide()\r\n\r\n/Users/aaronmeurer/Documents/pudb/pudb/debugger.pyc in interaction(self, exc_tuple)\r\n   1357 \r\n   1358         self.caption.set_text(caption)\r\n-> 1359         self.event_loop()\r\n   1360 \r\n   1361     def set_current_file(self, fname):\r\n\r\n/Users/aaronmeurer/Documents/pudb/pudb/debugger.pyc in event_loop(self, toplevel)\r\n   1316                         self.size = self.screen.get_cols_rows()\r\n   1317                     else:\r\n-> 1318                         toplevel.keypress(self.size, k)\r\n   1319 \r\n   1320             return self.quit_event_loop\r\n\r\n/Users/aaronmeurer/Documents/pudb/pudb/ui_tools.pyc in keypress(self, size, key)\r\n     85             for mask, handler in self.event_listeners:\r\n     86                 if mask is None or mask == key:\r\n---> 87                     return handler(self, size, key)\r\n     88 \r\n     89         return result\r\n\r\n/Users/aaronmeurer/Documents/pudb/pudb/debugger.pyc in run_shell(w, size, key)\r\n   1025 \r\n   1026             runner(curframe.f_locals, curframe.f_globals,\r\n-> 1027                     first_shell_run)\r\n   1028 \r\n   1029             self.screen.start()\r\n\r\n/Users/aaronmeurer/Documents/pudb/pudb/shell.pyc in run_ipython_shell_v11(locals, globals, first_time)\r\n    106     old_globals = shell.user_global_ns\r\n    107     # Update shell with current namespace\r\n\r\n--> 108     _update_ns(shell, locals, globals)\r\n    109     shell.mainloop(banner)\r\n    110     # Restore originating namespace\r\n\r\n\r\n/Users/aaronmeurer/Documents/pudb/pudb/shell.pyc in _update_ns(shell, locals, globals)\r\n    114     \'\'\'Update the IPython 0.11 namespace at every visit\'\'\'\r\n    115     shell.user_ns = locals.copy()\r\n--> 116     shell.user_global_ns = globals\r\n    117     shell.init_user_ns()\r\n    118     shell.init_completer()\r\n\r\nAttributeError: can\'t set attribute\r\n```\r\n\r\nThen, when I execute any command that produces an Out result, I get:\r\n\r\n```py\r\nIn [8]: 1\r\nOut[8]: 1\r\n---------------------------------------------------------------------------\r\nKeyError                                  Traceback (most recent call last)\r\n/Users/aaronmeurer/Documents/Python/sympy/sympy/<ipython-input-8-b026324c6904> in <module>()\r\n----> 1 1\r\n\r\n/Users/aaronmeurer/Documents/ipython/IPython/core/displayhook.py in __call__(self, result)\r\n    238             format_dict = self.compute_format_data(result)\r\n    239             self.write_format_data(format_dict)\r\n--> 240             self.update_user_ns(result)\r\n    241             self.log_output(format_dict)\r\n    242             self.finish_displayhook()\r\n\r\n/Users/aaronmeurer/Documents/ipython/IPython/core/displayhook.py in update_user_ns(self, result)\r\n    186 \r\n    187         # Avoid recursive reference when displaying _oh/Out\r\n\r\n--> 188         if result is not self.shell.user_ns[\'_oh\']:\r\n    189             if len(self.shell.user_ns[\'_oh\']) >= self.cache_size and self.do_full_cache:\r\n    190                 warn(\'Output cache limit (currently \'+\r\n\r\nKeyError: \'_oh\'\r\n```\r\n\r\nAnd finally, when I CTRL-D, I get\r\n\r\n```pytb\r\nError in atexit._run_exitfuncs:\r\nTraceback (most recent call last):\r\n  File ""/sw/lib/python2.7/atexit.py"", line 24, in _run_exitfuncs\r\n    func(*targs, **kargs)\r\n  File ""/Users/aaronmeurer/Documents/ipython/IPython/core/interactiveshell.py"", line 2743, in atexit_operations\r\n    self.reset(new_session=False)\r\n  File ""/Users/aaronmeurer/Documents/ipython/IPython/core/interactiveshell.py"", line 1131, in reset\r\n    self.displayhook.flush()\r\n  File ""/Users/aaronmeurer/Documents/ipython/IPython/core/displayhook.py"", line 255, in flush\r\n    self.shell.user_ns[\'_oh\'].clear()\r\nKeyError: \'_oh\'\r\nError in sys.exitfunc:\r\nTraceback (most recent call last):\r\n  File ""/sw/lib/python2.7/atexit.py"", line 24, in _run_exitfuncs\r\n    func(*targs, **kargs)\r\n  File ""/Users/aaronmeurer/Documents/ipython/IPython/core/interactiveshell.py"", line 2743, in atexit_operations\r\n    self.reset(new_session=False)\r\n  File ""/Users/aaronmeurer/Documents/ipython/IPython/core/interactiveshell.py"", line 1131, in reset\r\n    self.displayhook.flush()\r\n  File ""/Users/aaronmeurer/Documents/ipython/IPython/core/displayhook.py"", line 255, in flush\r\n    self.shell.user_ns[\'_oh\'].clear()\r\nKeyError: \'_oh\'\r\n```\r\n\r\nwhich kills everything and brings me back to bash (I think there are two tracebacks because I started pudb from within IPython).'"
BIDData/BIDMach#31,58948937,helgammal,helgammal,2015-02-25 18:35:31,2015-02-25 21:07:18,2015-02-25 21:07:18,closed,,,1,,https://api.github.com/repos/BIDData/BIDMach/issues/31,"b""IPython notebook in tutorials report that the 'kernel died'""","b""A minor annoyance: when opening the tutorials (via './bidmach notebook') and browsing to the tutorials then clicking any one tutorial, we get this message from IPython. \r\n![image](https://cloud.githubusercontent.com/assets/7671960/6377520/74609686-bcd9-11e4-8d64-97009ff40c01.png)\r\n\r\nFollowed by this: \r\n![image](https://cloud.githubusercontent.com/assets/7671960/6377526/8ba572c6-bcd9-11e4-8237-e677169cbcac.png)\r\n\r\nI looked at this and it might be a false alarm from IPython and there is a suggested solution [here] (https://github.com/ipython/ipython/issues/1198/)."""
matplotlib/matplotlib#1530,8631771,jfmoulin,efiring,2012-11-24 16:32:20,2013-05-24 19:28:41,2013-05-24 19:28:41,closed,,,14,confirmed bug,https://api.github.com/repos/matplotlib/matplotlib/issues/1530,b'saving a figure triggers (very) excessive IO activity ',"b'Saving a figure from the GUI under GTK triggers a lot of IO activity. Up to 60Mb/sec on my system.\nThe file /.local/share/recently-used.xbel gets written to each time the session history is scrolled through with cursor keys.\n\nI am running matplotlib 1.2.0 but this issue is, I believe, much older than that. \n\nI reported the issue to IPython (see https://github.com/ipython/ipython/issues/2608) first thinking this was a purely IPy problem but I could then reproduce the bug in a normal python session.\n\nAs suggested by rkern there, I posted a dump of strace and lsof at http://filebin.ca/NdspC6wfTV3\n\nAnother user also reported that saving from script triggers the same problem, but I could personnally not observe that with certainty.'"
astropy/astropy#4975,156746857,keflavich,,2016-05-25 13:11:09,2016-06-03 04:38:30,None,open,,,8,utils,https://api.github.com/repos/astropy/astropy/issues/4975,b'Avoid anonymous exception catching',"b'When running loops with ProgressBar, catching anonymous exceptions with a block like\n\n```\n    try:\n        ...\n    except:\n        ...\n```\n\ncatches, and therefore prevents the use of, `KeyboardInterrupt`s.  This PR\ncatches and *raises* `KeyboardInterrupt`s.\n\nThere are many other cases in astropy where anonymous exception catching is\nused; probably all of these cases should be modified to reraise\n`KeyboardInterrupt`s, but I would like to put that off til after we handle this\nissue as this one is urgent for my present work.'"
revolunet/sublimetext-google-apps-scripts#7,27431750,Buravchik,,2014-02-12 13:06:30,2014-06-17 01:55:25,None,open,,,17,,https://api.github.com/repos/revolunet/sublimetext-google-apps-scripts/issues/7,b'Plugin does not work',"b'Log from fresh startup:\r\n\r\nstartup, version: 2221 windows x32 channel: stable\r\nexecutable: /C/Program Files/Sublime Text 2/sublime_text.exe\r\nworking dir: /C/Windows/system32\r\npackages path: /C/Users/User/AppData/Roaming/Sublime Text 2/Packages\r\nsettings path: /C/Users/User/AppData/Roaming/Sublime Text 2/Settings\r\nsource packages: 49 installed packages: 48, running PackageSetup\r\nPy_GetProgramName(): sublime_text.exe\r\nPy_GetExecPrefix(): C:\\Program Files\\Sublime Text 2\r\nPy_GetProgramFullPath(): C:\\Program Files\\Sublime Text 2\\sublime_text.exe\r\nPy_GetPath(): C:\\Program Files\\Sublime Text 2\\python26.zip;C:\\Program Files\\Sublime Text 2\\DLLs;C:\\Program Files\\Sublime Text 2\\lib;C:\\Program Files\\Sublime Text 2\\lib\\plat-win;C:\\Program Files\\Sublime Text 2\\lib\\lib-tk;C:\\Program Files\\Sublime Text 2\r\nPy_GetPythonHome(): C:\\Program Files\\Sublime Text 2\r\nPackageSetup returned: -1\r\ncatalogue loaded\r\nfound 4 files for base name Default.sublime-keymap\r\nfound 1 files for base name Default.sublime-mousemap\r\nfound 2 files for base name Main.sublime-menu\r\nReloading plugin C:\\Users\\User\\AppData\\Roaming\\Sublime Text 2\\Packages\\CSS\\css_completions.py\r\nReloading plugin C:\\Users\\User\\AppData\\Roaming\\Sublime Text 2\\Packages\\Default\\comment.py\r\nReloading plugin C:\\Users\\User\\AppData\\Roaming\\Sublime Text 2\\Packages\\Default\\copy_path.py\r\nReloading plugin C:\\Users\\User\\AppData\\Roaming\\Sublime Text 2\\Packages\\Default\\delete_word.py\r\nReloading plugin C:\\Users\\User\\AppData\\Roaming\\Sublime Text 2\\Packages\\Default\\detect_indentation.py\r\nReloading plugin C:\\Users\\User\\AppData\\Roaming\\Sublime Text 2\\Packages\\Default\\duplicate_line.py\r\nReloading plugin C:\\Users\\User\\AppData\\Roaming\\Sublime Text 2\\Packages\\Default\\echo.py\r\nReloading plugin C:\\Users\\User\\AppData\\Roaming\\Sublime Text 2\\Packages\\Default\\exec.py\r\nReloading plugin C:\\Users\\User\\AppData\\Roaming\\Sublime Text 2\\Packages\\Default\\fold.py\r\nReloading plugin C:\\Users\\User\\AppData\\Roaming\\Sublime Text 2\\Packages\\Default\\font.py\r\nReloading plugin C:\\Users\\User\\AppData\\Roaming\\Sublime Text 2\\Packages\\Default\\goto_line.py\r\nReloading plugin C:\\Users\\User\\AppData\\Roaming\\Sublime Text 2\\Packages\\Default\\indentation.py\r\nReloading plugin C:\\Users\\User\\AppData\\Roaming\\Sublime Text 2\\Packages\\Default\\kill_ring.py\r\nReloading plugin C:\\Users\\User\\AppData\\Roaming\\Sublime Text 2\\Packages\\Default\\mark.py\r\nReloading plugin C:\\Users\\User\\AppData\\Roaming\\Sublime Text 2\\Packages\\Default\\new_templates.py\r\nReloading plugin C:\\Users\\User\\AppData\\Roaming\\Sublime Text 2\\Packages\\Default\\open_file_settings.py\r\nReloading plugin C:\\Users\\User\\AppData\\Roaming\\Sublime Text 2\\Packages\\Default\\open_in_browser.py\r\nReloading plugin C:\\Users\\User\\AppData\\Roaming\\Sublime Text 2\\Packages\\Default\\paragraph.py\r\nReloading plugin C:\\Users\\User\\AppData\\Roaming\\Sublime Text 2\\Packages\\Default\\save_on_focus_lost.py\r\nReloading plugin C:\\Users\\User\\AppData\\Roaming\\Sublime Text 2\\Packages\\Default\\scroll.py\r\nReloading plugin C:\\Users\\User\\AppData\\Roaming\\Sublime Text 2\\Packages\\Default\\set_unsaved_view_name.py\r\nReloading plugin C:\\Users\\User\\AppData\\Roaming\\Sublime Text 2\\Packages\\Default\\side_bar.py\r\nReloading plugin C:\\Users\\User\\AppData\\Roaming\\Sublime Text 2\\Packages\\Default\\sort.py\r\nReloading plugin C:\\Users\\User\\AppData\\Roaming\\Sublime Text 2\\Packages\\Default\\swap_line.py\r\nReloading plugin C:\\Users\\User\\AppData\\Roaming\\Sublime Text 2\\Packages\\Default\\switch_file.py\r\nReloading plugin C:\\Users\\User\\AppData\\Roaming\\Sublime Text 2\\Packages\\Default\\transform.py\r\nReloading plugin C:\\Users\\User\\AppData\\Roaming\\Sublime Text 2\\Packages\\Default\\transpose.py\r\nReloading plugin C:\\Users\\User\\AppData\\Roaming\\Sublime Text 2\\Packages\\Default\\trim_trailing_white_space.py\r\nReloading plugin C:\\Users\\User\\AppData\\Roaming\\Sublime Text 2\\Packages\\Diff\\diff.py\r\nReloading plugin C:\\Users\\User\\AppData\\Roaming\\Sublime Text 2\\Packages\\HTML\\encode_html_entities.py\r\nReloading plugin C:\\Users\\User\\AppData\\Roaming\\Sublime Text 2\\Packages\\HTML\\html_completions.py\r\nReloading plugin C:\\Users\\User\\AppData\\Roaming\\Sublime Text 2\\Packages\\Package Control\\Package Control.py\r\nplugin init time: 1.32996\r\nloading bindings\r\nloading pointer bindings\r\nfound 1 files for base name Default.sublime-theme\r\ntheme loaded\r\napp ready\r\npre session restore time: 3.02609\r\nwrote startup cache, added files: 6 orphaned files: 0 total files: 96 cache hits: 90\r\nstartup time: 3.24853 (package setup was run)\r\nloaded 837 snippets\r\nreloading /C/Users/User/AppData/Roaming/Sublime Text 2/Packages/User/Package Control.sublime-settings\r\nPackage Control: No updated packages\r\nignored packages updated to: [Vintage, Google Apps Scripts]\r\nfound 1 files for base name Default.sublime-theme\r\nreloading /C/Users/User/AppData/Roaming/Sublime Text 2/Packages/User/Preferences.sublime-settings\r\nfound 1 files for base name Default.sublime-theme\r\ntheme loaded\r\ntheme loaded\r\nignored packages updated to: [Vintage]\r\nfound 1 files for base name Default.sublime-theme\r\nreloading /C/Users/User/AppData/Roaming/Sublime Text 2/Packages/User/Package Control.sublime-settings\r\nreloading /C/Users/User/AppData/Roaming/Sublime Text 2/Packages/User/Preferences.sublime-settings\r\nfound 1 files for base name Default.sublime-theme\r\nReloading plugin C:\\Users\\User\\AppData\\Roaming\\Sublime Text 2\\Packages\\Google Apps Scripts\\GoogleAppsScripts.py\r\nTraceback (most recent call last):\r\n  File "".\\sublime_plugin.py"", line 62, in reload_plugin\r\n  File "".\\GoogleAppsScripts.py"", line 17, in <module>\r\n    import ScriptsBrowser\r\n  File "".\\ScriptsBrowser.py"", line 19, in <module>\r\n    import GoogleOAuth2\r\n  File ""C:\\Users\\User\\AppData\\Roaming\\Sublime Text 2\\Packages\\Google Apps Scripts\\lib\\GoogleOAuth2.py"", line 4, in <module>\r\n    import httplib2\r\n  File ""C:\\Users\\User\\AppData\\Roaming\\Sublime Text 2\\Packages\\Google Apps Scripts\\lib\\httplib2\\__init__.py"", line 95, in <module>\r\n    from iri2uri import iri2uri\r\n  File ""C:\\Users\\User\\AppData\\Roaming\\Sublime Text 2\\Packages\\Google Apps Scripts\\lib\\httplib2\\iri2uri.py"", line 100\r\n    self.assertEqual(""http://xn--o3h.com/%E2%98%84"", iri2uri(u""http://\\N{COMET}.com/\\N{COMET}""))\r\nSyntaxError: (unicode error) \\N escapes not supported (can\'t load unicodedata module)\r\nReloading plugin C:\\Users\\User\\AppData\\Roaming\\Sublime Text 2\\Packages\\Google Apps Scripts\\ScriptsBrowser.py\r\nTraceback (most recent call last):\r\n  File "".\\sublime_plugin.py"", line 62, in reload_plugin\r\n  File "".\\ScriptsBrowser.py"", line 19, in <module>\r\n    import GoogleOAuth2\r\n  File ""C:\\Users\\User\\AppData\\Roaming\\Sublime Text 2\\Packages\\Google Apps Scripts\\lib\\GoogleOAuth2.py"", line 4, in <module>\r\n    import httplib2\r\n  File ""C:\\Users\\User\\AppData\\Roaming\\Sublime Text 2\\Packages\\Google Apps Scripts\\lib\\httplib2\\__init__.py"", line 95, in <module>\r\n    from iri2uri import iri2uri\r\n  File ""C:\\Users\\User\\AppData\\Roaming\\Sublime Text 2\\Packages\\Google Apps Scripts\\lib\\httplib2\\iri2uri.py"", line 100\r\n    self.assertEqual(""http://xn--o3h.com/%E2%98%84"", iri2uri(u""http://\\N{COMET}.com/\\N{COMET}""))\r\nSyntaxError: (unicode error) \\N escapes not supported (can\'t load unicodedata module)\r\nReloading plugin C:\\Users\\User\\AppData\\Roaming\\Sublime Text 2\\Packages\\Google Apps Scripts\\SublimeHelper.py\r\nfound 3 files for base name Main.sublime-menu\r\ntheme loaded\r\ntheme loaded\r\n'"
,,,,,,,,,,,,,,
,,,,,,,,,,,,,,
pyinstaller/pyinstaller#631,46176695,pyinstaller-tickets-migration,matysek,2014-10-18 14:29:00,2014-10-18 14:29:10,2014-10-18 14:29:08,closed,matysek,PyInstaller 2.1,5,@low;develop,https://api.github.com/repos/pyinstaller/pyinstaller/issues/631,b'Hook for embedded IPython',"b'**Original date**: 2012/11/19\n**Original reporter**: *eu AND doxos DOT eu*\n\nI have a program which contains embedded IPython. IPython creates configuration files when started for the first time and shows the `README_STARTUP` file. Since IPython knows about `sys.frozen` ([code](https://github.com/ipython/ipython/blob/master/IPython/utils/path.py#L195)), it will correctly look for its resources where the `.exe.` file is. The attached hook copies those files over.'"
eschulte/emacs24-starter-kit#27,5235821,stephenLee,eschulte,2012-06-24 13:59:40,2012-09-13 22:54:10,2012-09-13 22:54:10,closed,,,2,,https://api.github.com/repos/eschulte/emacs24-starter-kit/issues/27,b'activate starter-kit-python error',"b'When I activate the python starter kit, it gives me a error: ""Symbol\'s value as variable is void: py-python-command""\nI use the newest GNU Emacs 24.1.1. I search the web and find something seems helpful. (https://github.com/ipython/ipython/issues/853)\nAnd I add this two lines :\n(setq ipython-command ""/usr/local/bin/ipython"")\n(setq py-python-command ""/usr/local/bin/ipython"") \nto starter-kit-python.el. But it doesn\'t work. \nDo you ever met this problem, how do you handle it?\n\nThanks!\n\n\n'"
dwb/jsonrpc2-zeromq-python#2,6180036,dovf,,2012-08-12 21:21:41,2015-03-04 14:07:42,None,open,,,2,,https://api.github.com/repos/dwb/jsonrpc2-zeromq-python/issues/2,"b'""ZMQError: Interrupted system call"" when used with Qt'","b""When a signal is received while polling on a socket, the interrupt is apparently propagated up to the application, and it is the application's responsibility to handle it correctly. Qt apparently causes signals to be sent in various situations. The end is result is that jsonrpc2_zeromq basically crashes when used in conjunction with Qt.\n\nThis is basically the same issue as reported on ipython: https://github.com/ipython/ipython/issues/499\n"""
matplotlib/matplotlib#5159,109096859,janschulz,,2015-09-30 14:00:40,2015-11-17 16:33:50,None,open,,unassigned,26,GUI/Qt;OS/Microsoft,https://api.github.com/repos/matplotlib/matplotlib/issues/5159,b'plt.plot(...) makes python repl in cmd slow',"b'When producing a small plot in the console, the console becomes very sluggish afterwards:\r\n\r\n```\r\n\xa6\xcb python\r\nPython 2.7.10 |Continuum Analytics, Inc.| (default, Sep 15 2015, 14:26:14) [MSC v.1500 64 bit (AMD64)] on win32\r\n\r\nType ""help"", ""copyright"", ""credits"" or ""license"" for more information.\r\nAnaconda is brought to you by Continuum Analytics.\r\nPlease check out: http://continuum.io/thanks and https://anaconda.org\r\n>>> import matplotlib.pyplot as plt\r\n>>> plt.plot([1,2,3], marker=""o"")\r\n[<matplotlib.lines.Line2D object at 0x0000000008DB60B8>]\r\n\r\n# from here on it\'s sluggish until I exit -> typing shows the next character\r\n# with a noteable delay and c&p is kind of ""typing"" the text instead of \r\n# almost instantly there\r\n\r\n>>> plt.show()\r\n```\r\n\r\nThis a clean new conda env py2.7 (`conda create -n mew_test python matplotlib seaborn ipython`) on windows7, 64bit. I also have cmder installed, but it also happens in the default cmd console'"
matplotlib/matplotlib#1530,8631771,jfmoulin,efiring,2012-11-24 16:32:20,2013-05-24 19:28:41,2013-05-24 19:28:41,closed,,,14,confirmed bug,https://api.github.com/repos/matplotlib/matplotlib/issues/1530,b'saving a figure triggers (very) excessive IO activity ',"b'Saving a figure from the GUI under GTK triggers a lot of IO activity. Up to 60Mb/sec on my system.\nThe file /.local/share/recently-used.xbel gets written to each time the session history is scrolled through with cursor keys.\n\nI am running matplotlib 1.2.0 but this issue is, I believe, much older than that. \n\nI reported the issue to IPython (see https://github.com/ipython/ipython/issues/2608) first thinking this was a purely IPy problem but I could then reproduce the bug in a normal python session.\n\nAs suggested by rkern there, I posted a dump of strace and lsof at http://filebin.ca/NdspC6wfTV3\n\nAnother user also reported that saving from script triggers the same problem, but I could personnally not observe that with certainty.'"
h5py/h5py#263,10801833,jeffteeters,andrewcollette,2013-02-08 23:46:23,2013-03-20 06:23:24,2013-03-16 17:22:20,closed,,2.2.0,9,,https://api.github.com/repos/h5py/h5py/issues/263,b'Two tests failed with UnicodeEncodeError',"b'System is Debian 6.0.4, Python 2.6.6; running tests on h5py 2.1.2.  Output shown below:\r\n<pre>\r\njt@core to_install/h5py-2.1.2$ python setup.py test\r\nrunning test\r\nrunning build_py\r\nrunning build_ext\r\nskipping \'h5py/defs.c\' Cython extension (up-to-date)\r\nskipping \'h5py/_errors.c\' Cython extension (up-to-date)\r\nskipping \'h5py/_objects.c\' Cython extension (up-to-date)\r\nskipping \'h5py/_proxy.c\' Cython extension (up-to-date)\r\nskipping \'h5py/h5fd.c\' Cython extension (up-to-date)\r\nskipping \'h5py/h5z.c\' Cython extension (up-to-date)\r\nskipping \'h5py/h5.c\' Cython extension (up-to-date)\r\nskipping \'h5py/h5i.c\' Cython extension (up-to-date)\r\nskipping \'h5py/h5r.c\' Cython extension (up-to-date)\r\nskipping \'h5py/utils.c\' Cython extension (up-to-date)\r\nskipping \'h5py/_conv.c\' Cython extension (up-to-date)\r\nskipping \'h5py/h5t.c\' Cython extension (up-to-date)\r\nskipping \'h5py/h5s.c\' Cython extension (up-to-date)\r\nskipping \'h5py/h5p.c\' Cython extension (up-to-date)\r\nskipping \'h5py/h5d.c\' Cython extension (up-to-date)\r\nskipping \'h5py/h5a.c\' Cython extension (up-to-date)\r\nskipping \'h5py/h5f.c\' Cython extension (up-to-date)\r\nskipping \'h5py/h5g.c\' Cython extension (up-to-date)\r\nskipping \'h5py/h5l.c\' Cython extension (up-to-date)\r\nskipping \'h5py/h5o.c\' Cython extension (up-to-date)\r\nskipping \'h5py/h5ds.c\' Cython extension (up-to-date)\r\n.................................................s...........................x................................E.......................E......sssss....................................sss..............................s......................\r\n======================================================================\r\nERROR: test_unicode (_hl.tests.test_file.TestUnicode)\r\nUnicode filenames can be used, and retrieved properly via .filename\r\n----------------------------------------------------------------------\r\nTraceback (most recent call last):\r\n  File ""/home/jt/to_install/h5py-2.1.2/build/lib.linux-i686-2.6/h5py/_hl/tests/test_file.py"", line 335, in test_unicode\r\n    fname = self.mktemp(prefix = u\'\\u201a\')\r\n  File ""/home/jt/to_install/h5py-2.1.2/build/lib.linux-i686-2.6/h5py/_hl/tests/common.py"", line 36, in mktemp\r\n    return tempfile.mktemp(suffix, prefix, dir=self.tempdir)\r\n  File ""/usr/lib/python2.6/tempfile.py"", line 351, in mktemp\r\n    if not _exists(file):\r\n  File ""/usr/lib/python2.6/tempfile.py"", line 101, in _exists\r\n    _stat(fn)\r\nUnicodeEncodeError: \'ascii\' codec can\'t encode character u\'\\u201a\' in position 22: ordinal not in range(128)\r\n\r\n======================================================================\r\nERROR: test_file (_hl.tests.test_base.TestRepr)\r\nFile object repr() with unicode\r\n----------------------------------------------------------------------\r\nTraceback (most recent call last):\r\n  File ""/home/jt/to_install/h5py-2.1.2/build/lib.linux-i686-2.6/h5py/_hl/tests/test_base.py"", line 67, in test_file\r\n    fname = tempfile.mktemp(self.USTRING+u\'.hdf5\')\r\n  File ""/usr/lib/python2.6/tempfile.py"", line 351, in mktemp\r\n    if not _exists(file):\r\n  File ""/usr/lib/python2.6/tempfile.py"", line 101, in _exists\r\n    _stat(fn)\r\nUnicodeEncodeError: \'ascii\' codec can\'t encode characters in position 14-15: ordinal not in range(128)\r\n\r\n----------------------------------------------------------------------\r\nRan 238 tests in 0.925s\r\n\r\nFAILED (errors=2, skipped=10, expected failures=1)\r\n</pre>'"
zeromq/pyzmq#95,756962,minrk,minrk,2011-04-11 23:17:40,2014-04-10 00:14:54,2011-04-12 23:12:08,closed,,,0,,https://api.github.com/repos/zeromq/pyzmq/issues/95,"b'Poller.register(s, 0) should unregister(s)'","b""This may or may not be a libzmq issue, but it comes up in pyzmq, because the ZMQStream.flush() operation sometimes calls poll with no events.\r\n\r\nIt is illegal to call the Windows 'select' function on a socket with events=0, but not illegal on POSIX.  Doing so will cause a hard crash in libzmq.\r\n"""
inducer/pudb#103,26850370,asmeurer,,2014-02-04 00:26:11,2014-11-13 20:20:05,None,open,,,9,Bug,https://api.github.com/repos/inducer/pudb/issues/103,b'Names not defined in list comprehension in the IPython shell',"b""In the IPython shell, you can't seem to access names from within list comprehensions:\r\n\r\n```py\r\nIn [16]: a = 1\r\n\r\nIn [17]: [a for i in range(10)]\r\n---------------------------------------------------------------------------\r\nNameError                                 Traceback (most recent call last)\r\n/Users/aaronmeurer/Documents/Continuum/conda/conda/resolve.py in <module>()\r\n----> 1 [a for i in range(10)]\r\n\r\n/Users/aaronmeurer/Documents/Continuum/conda/conda/resolve.py in <listcomp>(.0)\r\n----> 1 [a for i in range(10)]\r\n\r\nNameError: global name 'a' is not defined\r\n```\r\n\r\nIt doesn't matter if the name was defined within the session or if it comes from the function you are debugging. This is debugging within a function scope, if that matters. """
scrapy/scrapy#794,37578363,andrix,pablohoffman,2014-07-10 16:13:02,2014-08-22 19:29:51,2014-08-22 19:29:51,closed,,,3,,https://api.github.com/repos/scrapy/scrapy/issues/794,b'Scrapy shell[ipython] - NameError exception when using already imported module within a lambda',"b""I was doing some testing on Scrapy shell and I found this bug (in Ipython standalone works OK):\r\n\r\n    $ scrapy shell # shell must call ipython\r\n    $ import re\r\n    $ f1 = lambda n: re.match('xxx', n, re.IGNORECASE)\r\n    $ f1('')\r\n    ---------------------------------------------------------------------------\r\n    NameError                                 Traceback (most recent call last)\r\n    <ipython-input-4-a3ec2df8ae39> in <module>()\r\n    ----> 1 f1('')\r\n    \r\n    <ipython-input-3-8945a0244946> in <lambda>(n)\r\n    ----> 1 f1 = lambda n: re.match('serving', n, re.IGNORECASE)\r\n    \r\n    NameError: global name 're' is not defined\r\n\r\nI have confirmed this issue with @kmike and @kalessin."""
zetaops/pyoko#43,127937986,zetaopsbot,evrenesat,2016-01-21 14:39:03,2016-02-02 09:08:10,2016-02-02 09:08:10,closed,,,0,,https://api.github.com/repos/zetaops/pyoko/issues/43,b'ipython embed problematic #5076',"b""According to this following ipython issue, the ```embed()``` used in the pyoko's Shell command\r\nhas some issues with scope of global variables.\r\n\r\nhttps://github.com/ipython/ipython/issues/62 \r\n\r\n#pyoko"""
amplab/ray#269,165872164,mehrdadn,robertnishihara,2016-07-15 20:34:58,2016-07-16 21:42:59,2016-07-16 21:42:59,closed,,,2,,https://api.github.com/repos/amplab/ray/issues/269,b'Run IPython shell without embedding',"b""Works around bug ipython/ipython#62 from 2010 which still hasn't been fixed.\r\n\r\nReady for merge."""
pycassa/pycassa#193,12932847,donspaulding,thobbs,2013-04-08 16:50:35,2014-04-10 20:27:27,2014-04-10 20:27:27,closed,,,1,,https://api.github.com/repos/pycassa/pycassa/issues/193,b'Pycassa Shell should change the way it starts IPython',"b'Django [recently committed a fix](https://github.com/django/django/pull/512) from an IPython core dev that changed the way they started up IPython.  It seems IPython does not encourage the use of `embed()` for full-blown shells, because [it can create problems](https://github.com/ipython/ipython/issues/62) with `locals()` and `globals()`, and it appears [Pycassa has a bug like this](http://stackoverflow.com/questions/11560327/getting-an-unexpected-nameerror-in-pycassashell-when-invoking-one-function-from).\r\n\r\nPycassa may want to consider implementing this new method of instantiating an IPython shell.  \r\n\r\n```python\r\ntry:\r\n    from IPython.frontend.terminal.ipapp import TerminalIPythonApp\r\n    app = TerminalIPythonApp.instance()\r\n    app.initialize(argv=[])\r\n    app.start()\r\nexcept ImportError:\r\n    # fall back to embed()?\r\n```'"
theatlantic/django#1,70797374,OaklandPeters,OaklandPeters,2015-04-24 21:21:57,2015-04-29 19:00:58,2015-04-29 19:00:58,closed,,,0,,https://api.github.com/repos/theatlantic/django/issues/1,b'Back-port of fix for globals in shell.',"b""This is a back-port of the official Django 1.6 bug-fix for the shell. The bug comes from [shell.py](https://github.com/theatlantic/django/blob/atl/1.4.x/django/core/management/commands/shell.py#L16-17) initializing a slightly incorrect\r\nversion of IPython -- it starts an embed version rather than a terminal (`TerminalIPythonApp`). Functions declared in the embed don't inherit modifications to the global namespace (see below example).\r\n\r\nThe fix is short and direct (see link in notes). I tested this manually, and could not find any reports online of problems with this - so it should be safe.\r\n\r\nThoughts?\r\n\r\nNotes\r\n========\r\nOfficial fix released in Django 1.6:\r\nhttps://github.com/django/django/commit/3570ff734e93f493e023b912c9a97101f605f7f5\r\n\r\nA discussion and diagnosis of the problem with `embed` in IPython:\r\nhttps://github.com/ipython/ipython/issues/62\r\n\r\nExample\r\n=========\r\n\r\nEveryone has encountered the following problem:\r\n```\r\nIn [1]: a = 1\r\n\r\nIn [2]: def f(x):\r\n   ...:     return a*x\r\n   ...:\r\n\r\nIn [3]: f(2)\r\n---------------------------------------------------------------------------\r\nNameError                                 Traceback (most recent call last)\r\n/Volumes/www/workspace/Atlantic-CMS/src/django/django/core/management/commands/shell.py in <module>()\r\n----> 1 f(2)\r\n\r\n/Volumes/www/workspace/Atlantic-CMS/src/django/django/core/management/commands/shell.py in f(x)\r\n      1 def f(x):\r\n----> 2     return a*x\r\n      3\r\n\r\nNameError: global name 'a' is not defined\r\n```\r\n\r\n"""
rootpy/rootpy#265,13632732,pwaller,ndawe,2013-04-25 10:53:27,2014-07-11 16:20:46,2013-06-11 10:48:06,closed,,,0,cleanup,https://api.github.com/repos/rootpy/rootpy/issues/265,b'`rootpy browse` should change the way it starts ipython',"b'The problem is that we have separate local and global namespaces, that means:\r\n\r\n```ipython\r\nIn [1]: import re\r\n\r\nIn [2]: locals()[""re""]\r\nOut[2]: <module \'re\' from \'/usr/lib64/python2.6/re.pyc\'>\r\n\r\nIn [3]: globals()[""re""]\r\n---------------------------------------------------------------------------\r\nKeyError                                  Traceback (most recent call last)\r\n/user1/pwaller/.local/src/rootpy/scripts/rootpy in <module>()\r\n----> 1 globals()[""re""]\r\n\r\nKeyError: \'re\'\r\n\r\nIn [4]: def test(): return re\r\n\r\nIn [5]: test()\r\n---------------------------------------------------------------------------\r\nNameError                                 Traceback (most recent call last)\r\n/user1/pwaller/.local/src/rootpy/scripts/rootpy in <module>()\r\n----> 1 test()\r\n\r\n/user1/pwaller/.local/src/rootpy/scripts/rootpy in test()\r\n----> 1 def test(): return re\r\n\r\nNameError: global name \'re\' is not defined\r\n```\r\n\r\nSee ipython/ipython#62'"
gotcha/ipdb#31,6869063,asfaltboy,gotcha,2012-09-14 07:09:37,2015-06-04 12:49:11,2014-12-22 16:41:51,closed,,,21,Released,https://api.github.com/repos/gotcha/ipdb/issues/31,b'Starting ipdb inside ipython breaks color coding (windows)',"b""Scenario:\n1. Run ipython (in windows), import and run a method that includes a call to ipdb (i just included `import ipdb; ipdb.set_trace()` inside a method that i imported in this case django's `makemessages.py`)\n2. Debugger starts but all the color coding is output as raw strings, like so:\n```\n> \xa1\xfb[1;32mc:\\users\\big\\envs\\appricot\\lib\\site-packages\\django\\core\\management\\commands\\makemessages.py\xa1\xfb[0m(184)\xa1\xfb[0;36mprocess_file\xa1\xfb\n[1;34m()\xa1\xfb[0m\n\xa1\xfb[1;32m    183 \xa1\xfb[1;33m        \xa1\xfb[1;32mimport\xa1\xfb[0m \xa1\xfb[0mipdb\xa1\xfb[0m\xa1\xfb[1;33m;\xa1\xfb[0m \xa1\xfb[0mipdb\xa1\xfb[0m\xa1\xfb[1;33m.\xa1\xfb[0m\xa1\xfb[0mset_trace\xa1\xfb[0m\xa1\xfb[1;33m(\xa1\xfb[0m\xa1\xfb[1;\n33m)\xa1\xfb[0m\xa1\xfb[1;33m\xa1\xfb[0m\xa1\xfb[0m\n\xa1\xfb[0m\xa1\xfb[1;32m--> 184 \xa1\xfb[1;33m        \xa1\xfb[0mthefile\xa1\xfb[0m \xa1\xfb[1;33m=\xa1\xfb[0m \xa1\xfb[0mfile\xa1\xfb[0m\xa1\xfb[1;33m\xa1\xfb[0m\xa1\xfb[0m\n\xa1\xfb[0m\xa1\xfb[1;32m    185 \xa1\xfb[1;33m        \xa1\xfb[0morig_file\xa1\xfb[0m \xa1\xfb[1;33m=\xa1\xfb[0m \xa1\xfb[0mos\xa1\xfb[0m\xa1\xfb[1;33m.\xa1\xfb[0m\xa1\xfb[0mpath\xa1\xfb[0m\xa1\xfb[1;33m.\xa1\xfb[0m\xa1\xfb[0mjoin\xa1\xfb[0m\xa1\xfb[1;33m\n(\xa1\xfb[0m\xa1\xfb[0mdirpath\xa1\xfb[0m\xa1\xfb[1;33m,\xa1\xfb[0m \xa1\xfb[0mfile\xa1\xfb[0m\xa1\xfb[1;33m)\xa1\xfb[0m\xa1\xfb[1;33m\xa1\xfb[0m\xa1\xfb[0m\n\xa1\xfb[0m\nipdb>\n```\n\n**Edit:** Just to clarify, my issue is reproducible on the first ipdb run, just by entering ipython and importing any module (sample.py) which includes the line `import ipdb;ipdb.set_trace()`"""
